Workbook

Sheet Цикл
A1: Микроцикл 1 | V1: =V9+V16+V23+V30+V37 -> 14983.6 | W1: =IFERROR(V1/AA1,0) -> 18.317359 | Z1: =Z9+Z16+Z23+Z30+Z37 -> #REF! | AA1: =AA9+AA16+AA23+AA30+AA37 -> 818 | AB1: =AB9+AB16+AB23+AB30+AB37 -> 0.19305556 | AG1: =IFERROR(ROUND(AD1/$Y1,2),) | AK1: =IFERROR(ROUND(AH1/$Y1,2),) | AO1: =IFERROR(ROUND(AL1/$Y1,2),) | AS1: =IFERROR(ROUND(AP1/$Y1,2),)
A2: Дата | B2: Нагрузка | C2: Упражнения | D2: Коэф. воздействия на организм(одно-/много - суставное упражнение) | E2: Множ | F2: Вес | G2: Пов | H2: Под | I2: % | J2: Вес | K2: Пов | L2: Под | M2: % | N2: Вес | O2: Пов | P2: Под | Q2: % | R2: Вес | S2: Пов | T2: Под | U2: % | V2: Тоннаж | W2: Сред.вес | X2: Инт.Отн | Y2: ПМ | Z2: Инт. Фунт | AA2: КПШ | AB2: Время | AD2: =IF(AG2<>0,(IFERROR(IF($Y2>50,MROUND($Y2*AG2,2.5),IF($Y2<15,MROUND($Y2*AG2,0.1),MROUND($Y2*AG2,1))),)),"") | AG2: 0 | AH2: =IF(AK2<>0,(IFERROR(IF($Y2>50,MROUND($Y2*AK2,2.5),IF($Y2<15,MROUND($Y2*AK2,0.1),MROUND($Y2*AK2,1))),)),"") | AK2: 0 | AL2: =IF(AO2<>0,(IFERROR(IF($Y2>50,MROUND($Y2*AO2,2.5),IF($Y2<15,MROUND($Y2*AO2,0.1),MROUND($Y2*AO2,1))),)),"") | AO2: 0 | AP2: =IF(AS2<>0,(IFERROR(IF($Y2>50,MROUND($Y2*AS2,2.5),IF($Y2<15,MROUND($Y2*AS2,0.1),MROUND($Y2*AS2,1))),)),"") | AS2: 0
A3: Пн | B3: Средняя | C3: Ягодичный мост со штангой | D3: 1 | F3: =IF(I3<>0,(IFERROR(IF($Y3>50,MROUND($Y3*I3,2.5),IF($Y3<15,MROUND($Y3*I3,0.1),MROUND($Y3*I3,1))),)),"") -> 32.5 | G3: 12 | H3: 1 | I3: 0.35 | J3: =IF(M3<>0,(IFERROR(IF($Y3>50,MROUND($Y3*M3,2.5),IF($Y3<15,MROUND($Y3*M3,0.1),MROUND($Y3*M3,1))),)),"") -> 42.5 | K3: 10 | L3: 2 | M3: 0.48 | N3: =IF(Q3<>0,(IFERROR(IF($Y3>50,MROUND($Y3*Q3,2.5),IF($Y3<15,MROUND($Y3*Q3,0.1),MROUND($Y3*Q3,1))),)),"") -> 50 | O3: 8 | P3: 2 | Q3: 0.55 | R3: =IF(U3<>0,(IFERROR(IF($Y3>50,MROUND($Y3*U3,2.5),IF($Y3<15,MROUND($Y3*U3,0.1),MROUND($Y3*U3,1))),)),"") | U3: 0 | V3: =(IF(ISNUMBER(F3),F3,1)*G3*H3+IF(ISNUMBER(J3),J3,1)*K3*L3+IF(ISNUMBER(N3),N3,1)*O3*P3+IF(ISNUMBER(R3),R3,1)*S3*T3)*IF(ISNUMBER(E3),E3,1) -> 2040 | W3: =IFERROR((IF(ISNUMBER(F3),F3,1)*G3*H3+IF(ISNUMBER(J3),J3,1)*K3*L3+IF(ISNUMBER(N3),N3,1)*O3*P3+IF(ISNUMBER(R3),R3,1)*S3*T3)*IF(ISNUMBER(E3),E3,1)/(G3*H3+K3*L3+O3*P3+S3*T3),0) -> 42.5 | X3: =ROUND(IFERROR((W3/(Y3*IF(ISNUMBER(E3),E3,1))),0),4) -> 0.4722 | Y3: 90 | Z3: =(IF(I3<30%,0,IF(I3<35%,F3*G3*H3*F!$B$33,IF(I3<40%,F3*G3*H3*F!$B$38,IF(I3<45%,F3*G3*H3*F!$B$43,IF(I3<50%,F3*G3*H3*F!$B$48,IF(I3=50%,F3*G3*H3*F!$B$50,IF(I3=51%,F3*G3*H3*F!$B$51,IF(I3=52%,F3*G3*H3*F!$B$52,IF(I3=53%,F3*G3*H3*F!$B$53,IF(I3=54%,F3*G3*H3*F!$B$54,IF(I3=55%,F3*G3*H3*F!$B$55,IF(I3=56%,F3*G3*H3*F!$B$56,IF(I3=57%,F3*G3*H3*F!$B$57,IF(I3=58%,F3*G3*H3*F!$B$58,IF(I3=59%,F3*G3*H3*F!$B$59,IF(I3=60%,F3*G3*H3*F!$B$60,IF(I3=61%,F3*G3*H3*F!$B$61,IF(I3=62%,F3*G3*H3*F!$B$62,IF(I3=63%,F3*G3*H3*F!$B$63,IF(I3=64%,F3*G3*H3*F!$B$64,IF(I3=65%,F3*G3*H3*F!$B$65,IF(I3=66%,F3*G3*H3*F!$B$66,IF(I3=67%,F3*G3*H3*F!$B$67,IF(I3=68%,F3*G3*H3*F!$B$68,IF(I3=69%,F3*G3*H3*F!$B$69,IF(I3=70%,F3*G3*H3*F!$B$70,IF(I3=71%,F3*G3*H3*F!$B$71,IF(I3=72%,F3*G3*H3*F!$B$72,IF(I3=73%,F3*G3*H3*F!$B$73,IF(I3=74%,F3*G3*H3*F!$B$74,IF(I3=75%,F3*G3*H3*F!$B$75,IF(I3=76%,F3*G3*H3*F!$B$76,IF(I3=77%,F3*G3*H3*F!$B$77,IF(I3=78%,F3*G3*H3*F!$B$78,IF(I3=79%,F3*G3*H3*F!$B$79,IF(I3=80%,F3*G3*H3*F!$B$80,IF(I3=81%,F3*G3*H3*F!$B$81,IF(I3=82%,F3*G3*H3*F!$B$82,IF(I3=83%,F3*G3*H3*F!$B$83,IF(I3=84%,F3*G3*H3*F!$B$84,IF(I3=85%,F3*G3*H3*F!$B$85,IF(I3=86%,F3*G3*H3*F!$B$86,IF(I3=87%,F3*G3*H3*F!$B$87,IF(I3=88%,F3*G3*H3*F!$B$88,IF(I3=89%,F3*G3*H3*F!$B$89,IF(I3=90%,F3*G3*H3*F!$B$90,IF(I3=91%,F3*G3*H3*F!$B$91,IF(I3=92%,F3*G3*H3*F!$B$92,IF(I3=93%,F3*G3*H3*F!$B$93,IF(I3=94%,F3*G3*H3*F!$B$94,IF(I3=95%,F3*G3*H3*F!$B$95,IF(I3=96%,F3*G3*H3*F!$B$96,IF(I3=97%,F3*G3*H3*F!$B$97,IF(I3=98%,F3*G3*H3*F!$B$98,IF(I3=99%,F3*G3*H3*F!$B$99,IF(I3>99%,F3*G3*H3*F!$B$100,))))))))))))))))))))))))))))))))))))))))))))))))))))))))+IF(M3<30%,0,IF(M3<35%,J3*K3*L3*F!$B$33,IF(M3<40%,J3*K3*L3*F!$B$38,IF(M3<45%,J3*K3*L3*F!$B$43,IF(M3<50%,J3*K3*L3*F!$B$48,IF(M3=50%,J3*K3*L3*F!$B$50,IF(M3=51%,J3*K3*L3*F!$B$51,IF(M3=52%,J3*K3*L3*F!$B$52,IF(M3=53%,J3*K3*L3*F!$B$53,IF(M3=54%,J3*K3*L3*F!$B$54,IF(M3=55%,J3*K3*L3*F!$B$55,IF(M3=56%,J3*K3*L3*F!$B$56,IF(M3=57%,J3*K3*L3*F!$B$57,IF(M3=58%,J3*K3*L3*F!$B$58,IF(M3=59%,J3*K3*L3*F!$B$59,IF(M3=60%,J3*K3*L3*F!$B$60,IF(M3=61%,J3*K3*L3*F!$B$61,IF(M3=62%,J3*K3*L3*F!$B$62,IF(M3=63%,J3*K3*L3*F!$B$63,IF(M3=64%,J3*K3*L3*F!$B$64,IF(M3=65%,J3*K3*L3*F!$B$65,IF(M3=66%,J3*K3*L3*F!$B$66,IF(M3=67%,J3*K3*L3*F!$B$67,IF(M3=68%,J3*K3*L3*F!$B$68,IF(M3=69%,J3*K3*L3*F!$B$69,IF(M3=70%,J3*K3*L3*F!$B$70,IF(M3=71%,J3*K3*L3*F!$B$71,IF(M3=72%,J3*K3*L3*F!$B$72,IF(M3=73%,J3*K3*L3*F!$B$73,IF(M3=74%,J3*K3*L3*F!$B$74,IF(M3=75%,J3*K3*L3*F!$B$75,IF(M3=76%,J3*K3*L3*F!$B$76,IF(M3=77%,J3*K3*L3*F!$B$77,IF(M3=78%,J3*K3*L3*F!$B$78,IF(M3=79%,J3*K3*L3*F!$B$79,IF(M3=80%,J3*K3*L3*F!$B$80,IF(M3=81%,J3*K3*L3*F!$B$81,IF(M3=82%,J3*K3*L3*F!$B$82,IF(M3=83%,J3*K3*L3*F!$B$83,IF(M3=84%,J3*K3*L3*F!$B$84,IF(M3=85%,J3*K3*L3*F!$B$85,IF(M3=86%,J3*K3*L3*F!$B$86,IF(M3=87%,J3*K3*L3*F!$B$87,IF(M3=88%,J3*K3*L3*F!$B$88,IF(M3=89%,J3*K3*L3*F!$B$89,IF(M3=90%,J3*K3*L3*F!$B$90,IF(M3=91%,J3*K3*L3*F!$B$91,IF(M3=92%,J3*K3*L3*F!$B$92,IF(M3=93%,J3*K3*L3*F!$B$93,IF(M3=94%,J3*K3*L3*F!$B$94,IF(M3=95%,J3*K3*L3*F!$B$95,IF(M3=96%,J3*K3*L3*F!$B$96,IF(M3=97%,J3*K3*L3*F!$B$97,IF(M3=98%,J3*K3*L3*F!$B$98,IF(M3=99%,J3*K3*L3*F!$B$99,IF(M3>99%,J3*K3*L3*F!$B$100,))))))))))))))))))))))))))))))))))))))))))))))))))))))))+IF(Q3<30%,0,IF(Q3<35%,N3*O3*P3*F!$B$33,IF(Q3<40%,N3*O3*P3*F!$B$38,IF(Q3<45%,N3*O3*P3*F!$B$43,IF(Q3<50%,N3*O3*P3*F!$B$48,IF(Q3=50%,N3*O3*P3*F!$B$50,IF(Q3=51%,N3*O3*P3*F!$B$51,IF(Q3=52%,N3*O3*P3*F!$B$52,IF(Q3=53%,N3*O3*P3*F!$B$53,IF(Q3=54%,N3*O3*P3*F!$B$54,IF(Q3=55%,N3*O3*P3*F!$B$55,IF(Q3=56%,N3*O3*P3*F!$B$56,IF(Q3=57%,N3*O3*P3*F!$B$57,IF(Q3=58%,N3*O3*P3*F!$B$58,IF(Q3=59%,N3*O3*P3*F!$B$59,IF(Q3=60%,N3*O3*P3*F!$B$60,IF(Q3=61%,N3*O3*P3*F!$B$61,IF(Q3=62%,N3*O3*P3*F!$B$62,IF(Q3=63%,N3*O3*P3*F!$B$63,IF(Q3=64%,N3*O3*P3*F!$B$64,IF(Q3=65%,N3*O3*P3*F!$B$65,IF(Q3=66%,N3*O3*P3*F!$B$66,IF(Q3=67%,N3*O3*P3*F!$B$67,IF(Q3=68%,N3*O3*P3*F!$B$68,IF(Q3=69%,N3*O3*P3*F!$B$69,IF(Q3=70%,N3*O3*P3*F!$B$70,IF(Q3=71%,N3*O3*P3*F!$B$71,IF(Q3=72%,N3*O3*P3*F!$B$72,IF(Q3=73%,N3*O3*P3*F!$B$73,IF(Q3=74%,N3*O3*P3*F!$B$74,IF(Q3=75%,N3*O3*P3*F!$B$75,IF(Q3=76%,N3*O3*P3*F!$B$76,IF(Q3=77%,N3*O3*P3*F!$B$77,IF(Q3=78%,N3*O3*P3*F!$B$78,IF(Q3=79%,N3*O3*P3*F!$B$79,IF(Q3=80%,N3*O3*P3*F!$B$80,IF(Q3=81%,N3*O3*P3*F!$B$81,IF(Q3=82%,N3*O3*P3*F!$B$82,IF(Q3=83%,N3*O3*P3*F!$B$83,IF(Q3=84%,N3*O3*P3*F!$B$84,IF(Q3=85%,N3*O3*P3*F!$B$85,IF(Q3=86%,N3*O3*P3*F!$B$86,IF(Q3=87%,N3*O3*P3*F!$B$87,IF(Q3=88%,N3*O3*P3*F!$B$88,IF(Q3=89%,N3*O3*P3*F!$B$89,IF(Q3=90%,N3*O3*P3*F!$B$90,IF(Q3=91%,N3*O3*P3*F!$B$91,IF(Q3=92%,N3*O3*P3*F!$B$92,IF(Q3=93%,N3*O3*P3*F!$B$93,IF(Q3=94%,N3*O3*P3*F!$B$94,IF(Q3=95%,N3*O3*P3*F!$B$95,IF(Q3=96%,N3*O3*P3*F!$B$96,IF(Q3=97%,N3*O3*P3*F!$B$97,IF(Q3=98%,N3*O3*P3*F!$B$98,IF(Q3=99%,N3*O3*P3*F!$B$99,IF(Q3>99%,N3*O3*P3*F!$B$100,))))))))))))))))))))))))))))))))))))))))))))))))))))))))+IF(U3<30%,0,IF(U3<35%,R3*S3*T3*F!$B$33,IF(U3<40%,R3*S3*T3*F!$B$38,IF(U3<45%,R3*S3*T3*F!$B$43,IF(U3<50%,R3*S3*T3*F!$B$48,IF(U3=50%,R3*S3*T3*F!$B$50,IF(U3=51%,R3*S3*T3*F!$B$51,IF(U3=52%,R3*S3*T3*F!$B$52,IF(U3=53%,R3*S3*T3*F!$B$53,IF(U3=54%,R3*S3*T3*F!$B$54,IF(U3=55%,R3*S3*T3*F!$B$55,IF(U3=56%,R3*S3*T3*F!$B$56,IF(U3=57%,R3*S3*T3*F!$B$57,IF(U3=58%,R3*S3*T3*F!$B$58,IF(U3=59%,R3*S3*T3*F!$B$59,IF(U3=60%,R3*S3*T3*F!$B$60,IF(U3=61%,R3*S3*T3*F!$B$61,IF(U3=62%,R3*S3*T3*F!$B$62,IF(U3=63%,R3*S3*T3*F!$B$63,IF(U3=64%,R3*S3*T3*F!$B$64,IF(U3=65%,R3*S3*T3*F!$B$65,IF(U3=66%,R3*S3*T3*F!$B$66,IF(U3=67%,R3*S3*T3*F!$B$67,IF(U3=68%,R3*S3*T3*F!$B$68,IF(U3=69%,R3*S3*T3*F!$B$69,IF(U3=70%,R3*S3*T3*F!$B$70,IF(U3=71%,R3*S3*T3*F!$B$71,IF(U3=72%,R3*S3*T3*F!$B$72,IF(U3=73%,R3*S3*T3*F!$B$73,IF(U3=74%,R3*S3*T3*F!$B$74,IF(U3=75%,R3*S3*T3*F!$B$75,IF(U3=76%,R3*S3*T3*F!$B$76,IF(U3=77%,R3*S3*T3*F!$B$77,IF(U3=78%,R3*S3*T3*F!$B$78,IF(U3=79%,R3*S3*T3*F!$B$79,IF(U3=80%,R3*S3*T3*F!$B$80,IF(U3=81%,R3*S3*T3*F!$B$81,IF(U3=82%,R3*S3*T3*F!$B$82,IF(U3=83%,R3*S3*T3*F!$B$83,IF(U3=84%,R3*S3*T3*F!$B$84,IF(U3=85%,R3*S3*T3*F!$B$85,IF(U3=86%,R3*S3*T3*F!$B$86,IF(U3=87%,R3*S3*T3*F!$B$87,IF(U3=88%,R3*S3*T3*F!$B$88,IF(U3=89%,R3*S3*T3*F!$B$89,IF(U3=90%,R3*S3*T3*F!$B$90,IF(U3=91%,R3*S3*T3*F!$B$91,IF(U3=92%,R3*S3*T3*F!$B$92,IF(U3=93%,R3*S3*T3*F!$B$93,IF(U3=94%,R3*S3*T3*F!$B$94,IF(U3=95%,R3*S3*T3*F!$B$95,IF(U3=96%,R3*S3*T3*F!$B$96,IF(U3=97%,R3*S3*T3*F!$B$97,IF(U3=98%,R3*S3*T3*F!$B$98,IF(U3=99%,R3*S3*T3*F!$B$99,IF(U3>99%,R3*S3*T3*F!$B$100)))))))))))))))))))))))))))))))))))))))))))))))))))))))))*IF(ISNUMBER(E3),E3,1)*IF(ISNUMBER(D3),D3,1) -> #REF! | AA3: =G3*H3+K3*L3+O3*P3+S3*T3 -> 48 | AB3: =(H3*(IF(I3<45%,0.5,IF(I3<55%,0.8,IF(I3<65%,0.9,IF(I3<75%,1,IF(I3<85%,1.1,1.2))))))+L3*(IF(M3<45%,0.5,IF(M3<55%,0.8,IF(M3<65%,0.9,IF(M3<75%,1,IF(M3<85%,1.1,1.2))))))+P3*(IF(Q3<45%,0.5,IF(Q3<55%,0.8,IF(Q3<65%,0.9,IF(Q3<75%,1,IF(Q3<85%,1.1,1.2))))))+T3*(IF(U3<45%,0.5,IF(U3<55%,0.8,IF(U3<65%,0.9,IF(U3<75%,1,IF(U3<85%,1.1,1.2)))))))*IF(D3>=0.8,6,IF(D3<=0.4,1.5,3)) -> 23.4
A4: 42331 | B4: Легкая | C4: Болгарские выпады | D4: 0.3 | F4: =IF(I4<>0,(IFERROR(IF($Y4>50,MROUND($Y4*I4,2.5),IF($Y4<15,MROUND($Y4*I4,0.1),MROUND($Y4*I4,1))),)),"") -> 12 | G4: 12 | H4: 3 | I4: 0.4 | J4: =IF(M4<>0,(IFERROR(IF($Y4>50,MROUND($Y4*M4,2.5),IF($Y4<15,MROUND($Y4*M4,0.1),MROUND($Y4*M4,1))),)),"") | M4: 0 | N4: =IF(Q4<>0,(IFERROR(IF($Y4>50,MROUND($Y4*Q4,2.5),IF($Y4<15,MROUND($Y4*Q4,0.1),MROUND($Y4*Q4,1))),)),"") | Q4: 0 | R4: =IF(U4<>0,(IFERROR(IF($Y4>50,MROUND($Y4*U4,2.5),IF($Y4<15,MROUND($Y4*U4,0.1),MROUND($Y4*U4,1))),)),"") | U4: 0 | V4: =(IF(ISNUMBER(F4),F4,1)*G4*H4+IF(ISNUMBER(J4),J4,1)*K4*L4+IF(ISNUMBER(N4),N4,1)*O4*P4+IF(ISNUMBER(R4),R4,1)*S4*T4)*IF(ISNUMBER(E4),E4,1) -> 432 | W4: =IFERROR((IF(ISNUMBER(F4),F4,1)*G4*H4+IF(ISNUMBER(J4),J4,1)*K4*L4+IF(ISNUMBER(N4),N4,1)*O4*P4+IF(ISNUMBER(R4),R4,1)*S4*T4)*IF(ISNUMBER(E4),E4,1)/(G4*H4+K4*L4+O4*P4+S4*T4),0) -> 12 | X4: =ROUND(IFERROR((W4/(Y4*IF(ISNUMBER(E4),E4,1))),0),2) -> 0.4 | Y4: 30 | Z4: =(IF(I4<30%,0,IF(I4<35%,F4*G4*H4*F!$B$33,IF(I4<40%,F4*G4*H4*F!$B$38,IF(I4<45%,F4*G4*H4*F!$B$43,IF(I4<50%,F4*G4*H4*F!$B$48,IF(I4=50%,F4*G4*H4*F!$B$50,IF(I4=51%,F4*G4*H4*F!$B$51,IF(I4=52%,F4*G4*H4*F!$B$52,IF(I4=53%,F4*G4*H4*F!$B$53,IF(I4=54%,F4*G4*H4*F!$B$54,IF(I4=55%,F4*G4*H4*F!$B$55,IF(I4=56%,F4*G4*H4*F!$B$56,IF(I4=57%,F4*G4*H4*F!$B$57,IF(I4=58%,F4*G4*H4*F!$B$58,IF(I4=59%,F4*G4*H4*F!$B$59,IF(I4=60%,F4*G4*H4*F!$B$60,IF(I4=61%,F4*G4*H4*F!$B$61,IF(I4=62%,F4*G4*H4*F!$B$62,IF(I4=63%,F4*G4*H4*F!$B$63,IF(I4=64%,F4*G4*H4*F!$B$64,IF(I4=65%,F4*G4*H4*F!$B$65,IF(I4=66%,F4*G4*H4*F!$B$66,IF(I4=67%,F4*G4*H4*F!$B$67,IF(I4=68%,F4*G4*H4*F!$B$68,IF(I4=69%,F4*G4*H4*F!$B$69,IF(I4=70%,F4*G4*H4*F!$B$70,IF(I4=71%,F4*G4*H4*F!$B$71,IF(I4=72%,F4*G4*H4*F!$B$72,IF(I4=73%,F4*G4*H4*F!$B$73,IF(I4=74%,F4*G4*H4*F!$B$74,IF(I4=75%,F4*G4*H4*F!$B$75,IF(I4=76%,F4*G4*H4*F!$B$76,IF(I4=77%,F4*G4*H4*F!$B$77,IF(I4=78%,F4*G4*H4*F!$B$78,IF(I4=79%,F4*G4*H4*F!$B$79,IF(I4=80%,F4*G4*H4*F!$B$80,IF(I4=81%,F4*G4*H4*F!$B$81,IF(I4=82%,F4*G4*H4*F!$B$82,IF(I4=83%,F4*G4*H4*F!$B$83,IF(I4=84%,F4*G4*H4*F!$B$84,IF(I4=85%,F4*G4*H4*F!$B$85,IF(I4=86%,F4*G4*H4*F!$B$86,IF(I4=87%,F4*G4*H4*F!$B$87,IF(I4=88%,F4*G4*H4*F!$B$88,IF(I4=89%,F4*G4*H4*F!$B$89,IF(I4=90%,F4*G4*H4*F!$B$90,IF(I4=91%,F4*G4*H4*F!$B$91,IF(I4=92%,F4*G4*H4*F!$B$92,IF(I4=93%,F4*G4*H4*F!$B$93,IF(I4=94%,F4*G4*H4*F!$B$94,IF(I4=95%,F4*G4*H4*F!$B$95,IF(I4=96%,F4*G4*H4*F!$B$96,IF(I4=97%,F4*G4*H4*F!$B$97,IF(I4=98%,F4*G4*H4*F!$B$98,IF(I4=99%,F4*G4*H4*F!$B$99,IF(I4>99%,F4*G4*H4*F!$B$100,))))))))))))))))))))))))))))))))))))))))))))))))))))))))+IF(M4<30%,0,IF(M4<35%,J4*K4*L4*F!$B$33,IF(M4<40%,J4*K4*L4*F!$B$38,IF(M4<45%,J4*K4*L4*F!$B$43,IF(M4<50%,J4*K4*L4*F!$B$48,IF(M4=50%,J4*K4*L4*F!$B$50,IF(M4=51%,J4*K4*L4*F!$B$51,IF(M4=52%,J4*K4*L4*F!$B$52,IF(M4=53%,J4*K4*L4*F!$B$53,IF(M4=54%,J4*K4*L4*F!$B$54,IF(M4=55%,J4*K4*L4*F!$B$55,IF(M4=56%,J4*K4*L4*F!$B$56,IF(M4=57%,J4*K4*L4*F!$B$57,IF(M4=58%,J4*K4*L4*F!$B$58,IF(M4=59%,J4*K4*L4*F!$B$59,IF(M4=60%,J4*K4*L4*F!$B$60,IF(M4=61%,J4*K4*L4*F!$B$61,IF(M4=62%,J4*K4*L4*F!$B$62,IF(M4=63%,J4*K4*L4*F!$B$63,IF(M4=64%,J4*K4*L4*F!$B$64,IF(M4=65%,J4*K4*L4*F!$B$65,IF(M4=66%,J4*K4*L4*F!$B$66,IF(M4=67%,J4*K4*L4*F!$B$67,IF(M4=68%,J4*K4*L4*F!$B$68,IF(M4=69%,J4*K4*L4*F!$B$69,IF(M4=70%,J4*K4*L4*F!$B$70,IF(M4=71%,J4*K4*L4*F!$B$71,IF(M4=72%,J4*K4*L4*F!$B$72,IF(M4=73%,J4*K4*L4*F!$B$73,IF(M4=74%,J4*K4*L4*F!$B$74,IF(M4=75%,J4*K4*L4*F!$B$75,IF(M4=76%,J4*K4*L4*F!$B$76,IF(M4=77%,J4*K4*L4*F!$B$77,IF(M4=78%,J4*K4*L4*F!$B$78,IF(M4=79%,J4*K4*L4*F!$B$79,IF(M4=80%,J4*K4*L4*F!$B$80,IF(M4=81%,J4*K4*L4*F!$B$81,IF(M4=82%,J4*K4*L4*F!$B$82,IF(M4=83%,J4*K4*L4*F!$B$83,IF(M4=84%,J4*K4*L4*F!$B$84,IF(M4=85%,J4*K4*L4*F!$B$85,IF(M4=86%,J4*K4*L4*F!$B$86,IF(M4=87%,J4*K4*L4*F!$B$87,IF(M4=88%,J4*K4*L4*F!$B$88,IF(M4=89%,J4*K4*L4*F!$B$89,IF(M4=90%,J4*K4*L4*F!$B$90,IF(M4=91%,J4*K4*L4*F!$B$91,IF(M4=92%,J4*K4*L4*F!$B$92,IF(M4=93%,J4*K4*L4*F!$B$93,IF(M4=94%,J4*K4*L4*F!$B$94,IF(M4=95%,J4*K4*L4*F!$B$95,IF(M4=96%,J4*K4*L4*F!$B$96,IF(M4=97%,J4*K4*L4*F!$B$97,IF(M4=98%,J4*K4*L4*F!$B$98,IF(M4=99%,J4*K4*L4*F!$B$99,IF(M4>99%,J4*K4*L4*F!$B$100,))))))))))))))))))))))))))))))))))))))))))))))))))))))))+IF(Q4<30%,0,IF(Q4<35%,N4*O4*P4*F!$B$33,IF(Q4<40%,N4*O4*P4*F!$B$38,IF(Q4<45%,N4*O4*P4*F!$B$43,IF(Q4<50%,N4*O4*P4*F!$B$48,IF(Q4=50%,N4*O4*P4*F!$B$50,IF(Q4=51%,N4*O4*P4*F!$B$51,IF(Q4=52%,N4*O4*P4*F!$B$52,IF(Q4=53%,N4*O4*P4*F!$B$53,IF(Q4=54%,N4*O4*P4*F!$B$54,IF(Q4=55%,N4*O4*P4*F!$B$55,IF(Q4=56%,N4*O4*P4*F!$B$56,IF(Q4=57%,N4*O4*P4*F!$B$57,IF(Q4=58%,N4*O4*P4*F!$B$58,IF(Q4=59%,N4*O4*P4*F!$B$59,IF(Q4=60%,N4*O4*P4*F!$B$60,IF(Q4=61%,N4*O4*P4*F!$B$61,IF(Q4=62%,N4*O4*P4*F!$B$62,IF(Q4=63%,N4*O4*P4*F!$B$63,IF(Q4=64%,N4*O4*P4*F!$B$64,IF(Q4=65%,N4*O4*P4*F!$B$65,IF(Q4=66%,N4*O4*P4*F!$B$66,IF(Q4=67%,N4*O4*P4*F!$B$67,IF(Q4=68%,N4*O4*P4*F!$B$68,IF(Q4=69%,N4*O4*P4*F!$B$69,IF(Q4=70%,N4*O4*P4*F!$B$70,IF(Q4=71%,N4*O4*P4*F!$B$71,IF(Q4=72%,N4*O4*P4*F!$B$72,IF(Q4=73%,N4*O4*P4*F!$B$73,IF(Q4=74%,N4*O4*P4*F!$B$74,IF(Q4=75%,N4*O4*P4*F!$B$75,IF(Q4=76%,N4*O4*P4*F!$B$76,IF(Q4=77%,N4*O4*P4*F!$B$77,IF(Q4=78%,N4*O4*P4*F!$B$78,IF(Q4=79%,N4*O4*P4*F!$B$79,IF(Q4=80%,N4*O4*P4*F!$B$80,IF(Q4=81%,N4*O4*P4*F!$B$81,IF(Q4=82%,N4*O4*P4*F!$B$82,IF(Q4=83%,N4*O4*P4*F!$B$83,IF(Q4=84%,N4*O4*P4*F!$B$84,IF(Q4=85%,N4*O4*P4*F!$B$85,IF(Q4=86%,N4*O4*P4*F!$B$86,IF(Q4=87%,N4*O4*P4*F!$B$87,IF(Q4=88%,N4*O4*P4*F!$B$88,IF(Q4=89%,N4*O4*P4*F!$B$89,IF(Q4=90%,N4*O4*P4*F!$B$90,IF(Q4=91%,N4*O4*P4*F!$B$91,IF(Q4=92%,N4*O4*P4*F!$B$92,IF(Q4=93%,N4*O4*P4*F!$B$93,IF(Q4=94%,N4*O4*P4*F!$B$94,IF(Q4=95%,N4*O4*P4*F!$B$95,IF(Q4=96%,N4*O4*P4*F!$B$96,IF(Q4=97%,N4*O4*P4*F!$B$97,IF(Q4=98%,N4*O4*P4*F!$B$98,IF(Q4=99%,N4*O4*P4*F!$B$99,IF(Q4>99%,N4*O4*P4*F!$B$100,))))))))))))))))))))))))))))))))))))))))))))))))))))))))+IF(U4<30%,0,IF(U4<35%,R4*S4*T4*F!$B$33,IF(U4<40%,R4*S4*T4*F!$B$38,IF(U4<45%,R4*S4*T4*F!$B$43,IF(U4<50%,R4*S4*T4*F!$B$48,IF(U4=50%,R4*S4*T4*F!$B$50,IF(U4=51%,R4*S4*T4*F!$B$51,IF(U4=52%,R4*S4*T4*F!$B$52,IF(U4=53%,R4*S4*T4*F!$B$53,IF(U4=54%,R4*S4*T4*F!$B$54,IF(U4=55%,R4*S4*T4*F!$B$55,IF(U4=56%,R4*S4*T4*F!$B$56,IF(U4=57%,R4*S4*T4*F!$B$57,IF(U4=58%,R4*S4*T4*F!$B$58,IF(U4=59%,R4*S4*T4*F!$B$59,IF(U4=60%,R4*S4*T4*F!$B$60,IF(U4=61%,R4*S4*T4*F!$B$61,IF(U4=62%,R4*S4*T4*F!$B$62,IF(U4=63%,R4*S4*T4*F!$B$63,IF(U4=64%,R4*S4*T4*F!$B$64,IF(U4=65%,R4*S4*T4*F!$B$65,IF(U4=66%,R4*S4*T4*F!$B$66,IF(U4=67%,R4*S4*T4*F!$B$67,IF(U4=68%,R4*S4*T4*F!$B$68,IF(U4=69%,R4*S4*T4*F!$B$69,IF(U4=70%,R4*S4*T4*F!$B$70,IF(U4=71%,R4*S4*T4*F!$B$71,IF(U4=72%,R4*S4*T4*F!$B$72,IF(U4=73%,R4*S4*T4*F!$B$73,IF(U4=74%,R4*S4*T4*F!$B$74,IF(U4=75%,R4*S4*T4*F!$B$75,IF(U4=76%,R4*S4*T4*F!$B$76,IF(U4=77%,R4*S4*T4*F!$B$77,IF(U4=78%,R4*S4*T4*F!$B$78,IF(U4=79%,R4*S4*T4*F!$B$79,IF(U4=80%,R4*S4*T4*F!$B$80,IF(U4=81%,R4*S4*T4*F!$B$81,IF(U4=82%,R4*S4*T4*F!$B$82,IF(U4=83%,R4*S4*T4*F!$B$83,IF(U4=84%,R4*S4*T4*F!$B$84,IF(U4=85%,R4*S4*T4*F!$B$85,IF(U4=86%,R4*S4*T4*F!$B$86,IF(U4=87%,R4*S4*T4*F!$B$87,IF(U4=88%,R4*S4*T4*F!$B$88,IF(U4=89%,R4*S4*T4*F!$B$89,IF(U4=90%,R4*S4*T4*F!$B$90,IF(U4=91%,R4*S4*T4*F!$B$91,IF(U4=92%,R4*S4*T4*F!$B$92,IF(U4=93%,R4*S4*T4*F!$B$93,IF(U4=94%,R4*S4*T4*F!$B$94,IF(U4=95%,R4*S4*T4*F!$B$95,IF(U4=96%,R4*S4*T4*F!$B$96,IF(U4=97%,R4*S4*T4*F!$B$97,IF(U4=98%,R4*S4*T4*F!$B$98,IF(U4=99%,R4*S4*T4*F!$B$99,IF(U4>99%,R4*S4*T4*F!$B$100)))))))))))))))))))))))))))))))))))))))))))))))))))))))))*IF(ISNUMBER(E4),E4,1)*IF(ISNUMBER(D4),D4,1) -> #REF! | AA4: =G4*H4+K4*L4+O4*P4+S4*T4 -> 36 | AB4: =(H4*(IF(I4<45%,0.5,IF(I4<55%,0.8,IF(I4<65%,0.9,IF(I4<75%,1,IF(I4<85%,1.1,1.2))))))+L4*(IF(M4<45%,0.5,IF(M4<55%,0.8,IF(M4<65%,0.9,IF(M4<75%,1,IF(M4<85%,1.1,1.2))))))+P4*(IF(Q4<45%,0.5,IF(Q4<55%,0.8,IF(Q4<65%,0.9,IF(Q4<75%,1,IF(Q4<85%,1.1,1.2))))))+T4*(IF(U4<45%,0.5,IF(U4<55%,0.8,IF(U4<65%,0.9,IF(U4<75%,1,IF(U4<85%,1.1,1.2)))))))*IF(D4>=0.8,6,IF(D4<=0.4,1.5,3)) -> 2.25
B5: Средняя | C5: Разведение ног в тренажёре | D5: 0.3 | E5: 5 | F5: =IF(I5<>0,(IFERROR(IF($Y5>50,MROUND($Y5*I5,2.5),IF($Y5<15,MROUND($Y5*I5,0.1),MROUND($Y5*I5,1))),)),"") -> 4.4 | G5: 12 | H5: 1 | I5: 0.44 | J5: =IF(M5<>0,(IFERROR(IF($Y5>50,MROUND($Y5*M5,2.5),IF($Y5<15,MROUND($Y5*M5,0.1),MROUND($Y5*M5,1))),)),"") -> 5 | K5: 10 | L5: 3 | M5: 0.5 | N5: =IF(Q5<>0,(IFERROR(IF($Y5>50,MROUND($Y5*Q5,2.5),IF($Y5<15,MROUND($Y5*Q5,0.1),MROUND($Y5*Q5,1))),)),"") | Q5: 0 | R5: =IF(U5<>0,(IFERROR(IF($Y5>50,MROUND($Y5*U5,2.5),IF($Y5<15,MROUND($Y5*U5,0.1),MROUND($Y5*U5,1))),)),"") | U5: 0 | V5: =(IF(ISNUMBER(F5),F5,1)*G5*H5+IF(ISNUMBER(J5),J5,1)*K5*L5+IF(ISNUMBER(N5),N5,1)*O5*P5+IF(ISNUMBER(R5),R5,1)*S5*T5)*IF(ISNUMBER(E5),E5,1) -> 1014 | W5: =IFERROR((IF(ISNUMBER(F5),F5,1)*G5*H5+IF(ISNUMBER(J5),J5,1)*K5*L5+IF(ISNUMBER(N5),N5,1)*O5*P5+IF(ISNUMBER(R5),R5,1)*S5*T5)*IF(ISNUMBER(E5),E5,1)/(G5*H5+K5*L5+O5*P5+S5*T5),0) -> 24.142857 | X5: =ROUND(IFERROR((W5/(Y5*IF(ISNUMBER(E5),E5,1))),0),2) -> 0.48 | Y5: 10 | Z5: =(IF(I5<30%,0,IF(I5<35%,F5*G5*H5*F!$B$33,IF(I5<40%,F5*G5*H5*F!$B$38,IF(I5<45%,F5*G5*H5*F!$B$43,IF(I5<50%,F5*G5*H5*F!$B$48,IF(I5=50%,F5*G5*H5*F!$B$50,IF(I5=51%,F5*G5*H5*F!$B$51,IF(I5=52%,F5*G5*H5*F!$B$52,IF(I5=53%,F5*G5*H5*F!$B$53,IF(I5=54%,F5*G5*H5*F!$B$54,IF(I5=55%,F5*G5*H5*F!$B$55,IF(I5=56%,F5*G5*H5*F!$B$56,IF(I5=57%,F5*G5*H5*F!$B$57,IF(I5=58%,F5*G5*H5*F!$B$58,IF(I5=59%,F5*G5*H5*F!$B$59,IF(I5=60%,F5*G5*H5*F!$B$60,IF(I5=61%,F5*G5*H5*F!$B$61,IF(I5=62%,F5*G5*H5*F!$B$62,IF(I5=63%,F5*G5*H5*F!$B$63,IF(I5=64%,F5*G5*H5*F!$B$64,IF(I5=65%,F5*G5*H5*F!$B$65,IF(I5=66%,F5*G5*H5*F!$B$66,IF(I5=67%,F5*G5*H5*F!$B$67,IF(I5=68%,F5*G5*H5*F!$B$68,IF(I5=69%,F5*G5*H5*F!$B$69,IF(I5=70%,F5*G5*H5*F!$B$70,IF(I5=71%,F5*G5*H5*F!$B$71,IF(I5=72%,F5*G5*H5*F!$B$72,IF(I5=73%,F5*G5*H5*F!$B$73,IF(I5=74%,F5*G5*H5*F!$B$74,IF(I5=75%,F5*G5*H5*F!$B$75,IF(I5=76%,F5*G5*H5*F!$B$76,IF(I5=77%,F5*G5*H5*F!$B$77,IF(I5=78%,F5*G5*H5*F!$B$78,IF(I5=79%,F5*G5*H5*F!$B$79,IF(I5=80%,F5*G5*H5*F!$B$80,IF(I5=81%,F5*G5*H5*F!$B$81,IF(I5=82%,F5*G5*H5*F!$B$82,IF(I5=83%,F5*G5*H5*F!$B$83,IF(I5=84%,F5*G5*H5*F!$B$84,IF(I5=85%,F5*G5*H5*F!$B$85,IF(I5=86%,F5*G5*H5*F!$B$86,IF(I5=87%,F5*G5*H5*F!$B$87,IF(I5=88%,F5*G5*H5*F!$B$88,IF(I5=89%,F5*G5*H5*F!$B$89,IF(I5=90%,F5*G5*H5*F!$B$90,IF(I5=91%,F5*G5*H5*F!$B$91,IF(I5=92%,F5*G5*H5*F!$B$92,IF(I5=93%,F5*G5*H5*F!$B$93,IF(I5=94%,F5*G5*H5*F!$B$94,IF(I5=95%,F5*G5*H5*F!$B$95,IF(I5=96%,F5*G5*H5*F!$B$96,IF(I5=97%,F5*G5*H5*F!$B$97,IF(I5=98%,F5*G5*H5*F!$B$98,IF(I5=99%,F5*G5*H5*F!$B$99,IF(I5>99%,F5*G5*H5*F!$B$100,))))))))))))))))))))))))))))))))))))))))))))))))))))))))+IF(M5<30%,0,IF(M5<35%,J5*K5*L5*F!$B$33,IF(M5<40%,J5*K5*L5*F!$B$38,IF(M5<45%,J5*K5*L5*F!$B$43,IF(M5<50%,J5*K5*L5*F!$B$48,IF(M5=50%,J5*K5*L5*F!$B$50,IF(M5=51%,J5*K5*L5*F!$B$51,IF(M5=52%,J5*K5*L5*F!$B$52,IF(M5=53%,J5*K5*L5*F!$B$53,IF(M5=54%,J5*K5*L5*F!$B$54,IF(M5=55%,J5*K5*L5*F!$B$55,IF(M5=56%,J5*K5*L5*F!$B$56,IF(M5=57%,J5*K5*L5*F!$B$57,IF(M5=58%,J5*K5*L5*F!$B$58,IF(M5=59%,J5*K5*L5*F!$B$59,IF(M5=60%,J5*K5*L5*F!$B$60,IF(M5=61%,J5*K5*L5*F!$B$61,IF(M5=62%,J5*K5*L5*F!$B$62,IF(M5=63%,J5*K5*L5*F!$B$63,IF(M5=64%,J5*K5*L5*F!$B$64,IF(M5=65%,J5*K5*L5*F!$B$65,IF(M5=66%,J5*K5*L5*F!$B$66,IF(M5=67%,J5*K5*L5*F!$B$67,IF(M5=68%,J5*K5*L5*F!$B$68,IF(M5=69%,J5*K5*L5*F!$B$69,IF(M5=70%,J5*K5*L5*F!$B$70,IF(M5=71%,J5*K5*L5*F!$B$71,IF(M5=72%,J5*K5*L5*F!$B$72,IF(M5=73%,J5*K5*L5*F!$B$73,IF(M5=74%,J5*K5*L5*F!$B$74,IF(M5=75%,J5*K5*L5*F!$B$75,IF(M5=76%,J5*K5*L5*F!$B$76,IF(M5=77%,J5*K5*L5*F!$B$77,IF(M5=78%,J5*K5*L5*F!$B$78,IF(M5=79%,J5*K5*L5*F!$B$79,IF(M5=80%,J5*K5*L5*F!$B$80,IF(M5=81%,J5*K5*L5*F!$B$81,IF(M5=82%,J5*K5*L5*F!$B$82,IF(M5=83%,J5*K5*L5*F!$B$83,IF(M5=84%,J5*K5*L5*F!$B$84,IF(M5=85%,J5*K5*L5*F!$B$85,IF(M5=86%,J5*K5*L5*F!$B$86,IF(M5=87%,J5*K5*L5*F!$B$87,IF(M5=88%,J5*K5*L5*F!$B$88,IF(M5=89%,J5*K5*L5*F!$B$89,IF(M5=90%,J5*K5*L5*F!$B$90,IF(M5=91%,J5*K5*L5*F!$B$91,IF(M5=92%,J5*K5*L5*F!$B$92,IF(M5=93%,J5*K5*L5*F!$B$93,IF(M5=94%,J5*K5*L5*F!$B$94,IF(M5=95%,J5*K5*L5*F!$B$95,IF(M5=96%,J5*K5*L5*F!$B$96,IF(M5=97%,J5*K5*L5*F!$B$97,IF(M5=98%,J5*K5*L5*F!$B$98,IF(M5=99%,J5*K5*L5*F!$B$99,IF(M5>99%,J5*K5*L5*F!$B$100,))))))))))))))))))))))))))))))))))))))))))))))))))))))))+IF(Q5<30%,0,IF(Q5<35%,N5*O5*P5*F!$B$33,IF(Q5<40%,N5*O5*P5*F!$B$38,IF(Q5<45%,N5*O5*P5*F!$B$43,IF(Q5<50%,N5*O5*P5*F!$B$48,IF(Q5=50%,N5*O5*P5*F!$B$50,IF(Q5=51%,N5*O5*P5*F!$B$51,IF(Q5=52%,N5*O5*P5*F!$B$52,IF(Q5=53%,N5*O5*P5*F!$B$53,IF(Q5=54%,N5*O5*P5*F!$B$54,IF(Q5=55%,N5*O5*P5*F!$B$55,IF(Q5=56%,N5*O5*P5*F!$B$56,IF(Q5=57%,N5*O5*P5*F!$B$57,IF(Q5=58%,N5*O5*P5*F!$B$58,IF(Q5=59%,N5*O5*P5*F!$B$59,IF(Q5=60%,N5*O5*P5*F!$B$60,IF(Q5=61%,N5*O5*P5*F!$B$61,IF(Q5=62%,N5*O5*P5*F!$B$62,IF(Q5=63%,N5*O5*P5*F!$B$63,IF(Q5=64%,N5*O5*P5*F!$B$64,IF(Q5=65%,N5*O5*P5*F!$B$65,IF(Q5=66%,N5*O5*P5*F!$B$66,IF(Q5=67%,N5*O5*P5*F!$B$67,IF(Q5=68%,N5*O5*P5*F!$B$68,IF(Q5=69%,N5*O5*P5*F!$B$69,IF(Q5=70%,N5*O5*P5*F!$B$70,IF(Q5=71%,N5*O5*P5*F!$B$71,IF(Q5=72%,N5*O5*P5*F!$B$72,IF(Q5=73%,N5*O5*P5*F!$B$73,IF(Q5=74%,N5*O5*P5*F!$B$74,IF(Q5=75%,N5*O5*P5*F!$B$75,IF(Q5=76%,N5*O5*P5*F!$B$76,IF(Q5=77%,N5*O5*P5*F!$B$77,IF(Q5=78%,N5*O5*P5*F!$B$78,IF(Q5=79%,N5*O5*P5*F!$B$79,IF(Q5=80%,N5*O5*P5*F!$B$80,IF(Q5=81%,N5*O5*P5*F!$B$81,IF(Q5=82%,N5*O5*P5*F!$B$82,IF(Q5=83%,N5*O5*P5*F!$B$83,IF(Q5=84%,N5*O5*P5*F!$B$84,IF(Q5=85%,N5*O5*P5*F!$B$85,IF(Q5=86%,N5*O5*P5*F!$B$86,IF(Q5=87%,N5*O5*P5*F!$B$87,IF(Q5=88%,N5*O5*P5*F!$B$88,IF(Q5=89%,N5*O5*P5*F!$B$89,IF(Q5=90%,N5*O5*P5*F!$B$90,IF(Q5=91%,N5*O5*P5*F!$B$91,IF(Q5=92%,N5*O5*P5*F!$B$92,IF(Q5=93%,N5*O5*P5*F!$B$93,IF(Q5=94%,N5*O5*P5*F!$B$94,IF(Q5=95%,N5*O5*P5*F!$B$95,IF(Q5=96%,N5*O5*P5*F!$B$96,IF(Q5=97%,N5*O5*P5*F!$B$97,IF(Q5=98%,N5*O5*P5*F!$B$98,IF(Q5=99%,N5*O5*P5*F!$B$99,IF(Q5>99%,N5*O5*P5*F!$B$100,))))))))))))))))))))))))))))))))))))))))))))))))))))))))+IF(U5<30%,0,IF(U5<35%,R5*S5*T5*F!$B$33,IF(U5<40%,R5*S5*T5*F!$B$38,IF(U5<45%,R5*S5*T5*F!$B$43,IF(U5<50%,R5*S5*T5*F!$B$48,IF(U5=50%,R5*S5*T5*F!$B$50,IF(U5=51%,R5*S5*T5*F!$B$51,IF(U5=52%,R5*S5*T5*F!$B$52,IF(U5=53%,R5*S5*T5*F!$B$53,IF(U5=54%,R5*S5*T5*F!$B$54,IF(U5=55%,R5*S5*T5*F!$B$55,IF(U5=56%,R5*S5*T5*F!$B$56,IF(U5=57%,R5*S5*T5*F!$B$57,IF(U5=58%,R5*S5*T5*F!$B$58,IF(U5=59%,R5*S5*T5*F!$B$59,IF(U5=60%,R5*S5*T5*F!$B$60,IF(U5=61%,R5*S5*T5*F!$B$61,IF(U5=62%,R5*S5*T5*F!$B$62,IF(U5=63%,R5*S5*T5*F!$B$63,IF(U5=64%,R5*S5*T5*F!$B$64,IF(U5=65%,R5*S5*T5*F!$B$65,IF(U5=66%,R5*S5*T5*F!$B$66,IF(U5=67%,R5*S5*T5*F!$B$67,IF(U5=68%,R5*S5*T5*F!$B$68,IF(U5=69%,R5*S5*T5*F!$B$69,IF(U5=70%,R5*S5*T5*F!$B$70,IF(U5=71%,R5*S5*T5*F!$B$71,IF(U5=72%,R5*S5*T5*F!$B$72,IF(U5=73%,R5*S5*T5*F!$B$73,IF(U5=74%,R5*S5*T5*F!$B$74,IF(U5=75%,R5*S5*T5*F!$B$75,IF(U5=76%,R5*S5*T5*F!$B$76,IF(U5=77%,R5*S5*T5*F!$B$77,IF(U5=78%,R5*S5*T5*F!$B$78,IF(U5=79%,R5*S5*T5*F!$B$79,IF(U5=80%,R5*S5*T5*F!$B$80,IF(U5=81%,R5*S5*T5*F!$B$81,IF(U5=82%,R5*S5*T5*F!$B$82,IF(U5=83%,R5*S5*T5*F!$B$83,IF(U5=84%,R5*S5*T5*F!$B$84,IF(U5=85%,R5*S5*T5*F!$B$85,IF(U5=86%,R5*S5*T5*F!$B$86,IF(U5=87%,R5*S5*T5*F!$B$87,IF(U5=88%,R5*S5*T5*F!$B$88,IF(U5=89%,R5*S5*T5*F!$B$89,IF(U5=90%,R5*S5*T5*F!$B$90,IF(U5=91%,R5*S5*T5*F!$B$91,IF(U5=92%,R5*S5*T5*F!$B$92,IF(U5=93%,R5*S5*T5*F!$B$93,IF(U5=94%,R5*S5*T5*F!$B$94,IF(U5=95%,R5*S5*T5*F!$B$95,IF(U5=96%,R5*S5*T5*F!$B$96,IF(U5=97%,R5*S5*T5*F!$B$97,IF(U5=98%,R5*S5*T5*F!$B$98,IF(U5=99%,R5*S5*T5*F!$B$99,IF(U5>99%,R5*S5*T5*F!$B$100)))))))))))))))))))))))))))))))))))))))))))))))))))))))))*IF(ISNUMBER(E5),E5,1)*IF(ISNUMBER(D5),D5,1) -> #REF! | AA5: =G5*H5+K5*L5+O5*P5+S5*T5 -> 42 | AB5: =(H5*(IF(I5<45%,0.5,IF(I5<55%,0.8,IF(I5<65%,0.9,IF(I5<75%,1,IF(I5<85%,1.1,1.2))))))+L5*(IF(M5<45%,0.5,IF(M5<55%,0.8,IF(M5<65%,0.9,IF(M5<75%,1,IF(M5<85%,1.1,1.2))))))+P5*(IF(Q5<45%,0.5,IF(Q5<55%,0.8,IF(Q5<65%,0.9,IF(Q5<75%,1,IF(Q5<85%,1.1,1.2))))))+T5*(IF(U5<45%,0.5,IF(U5<55%,0.8,IF(U5<65%,0.9,IF(U5<75%,1,IF(U5<85%,1.1,1.2)))))))*IF(D5>=0.8,6,IF(D5<=0.4,1.5,3)) -> 4.35
B6: Тяжелая | C6: Присед | D6: 1.2 | F6: =IF(I6<>0,(IFERROR(IF($Y6>50,MROUND($Y6*I6,2.5),IF($Y6<15,MROUND($Y6*I6,0.1),MROUND($Y6*I6,1))),)),"") -> 20 | G6: 12 | H6: 1 | I6: 0.4 | J6: =IF(M6<>0,(IFERROR(IF($Y6>50,MROUND($Y6*M6,2.5),IF($Y6<15,MROUND($Y6*M6,0.1),MROUND($Y6*M6,1))),)),"") -> 30 | K6: 10 | L6: 4 | M6: 0.6 | N6: =IF(Q6<>0,(IFERROR(IF($Y6>50,MROUND($Y6*Q6,2.5),IF($Y6<15,MROUND($Y6*Q6,0.1),MROUND($Y6*Q6,1))),)),"") | Q6: 0 | R6: =IF(U6<>0,(IFERROR(IF($Y6>50,MROUND($Y6*U6,2.5),IF($Y6<15,MROUND($Y6*U6,0.1),MROUND($Y6*U6,1))),)),"") | U6: 0 | V6: =(IF(ISNUMBER(F6),F6,1)*G6*H6+IF(ISNUMBER(J6),J6,1)*K6*L6+IF(ISNUMBER(N6),N6,1)*O6*P6+IF(ISNUMBER(R6),R6,1)*S6*T6)*IF(ISNUMBER(E6),E6,1) -> 1440 | W6: =IFERROR((IF(ISNUMBER(F6),F6,1)*G6*H6+IF(ISNUMBER(J6),J6,1)*K6*L6+IF(ISNUMBER(N6),N6,1)*O6*P6+IF(ISNUMBER(R6),R6,1)*S6*T6)*IF(ISNUMBER(E6),E6,1)/(G6*H6+K6*L6+O6*P6+S6*T6),0) -> 27.692308 | X6: =ROUND(IFERROR((W6/(Y6*IF(ISNUMBER(E6),E6,1))),0),2) -> 0.55 | Y6: 50 | Z6: =(IF(I6<30%,0,IF(I6<35%,F6*G6*H6*F!$B$33,IF(I6<40%,F6*G6*H6*F!$B$38,IF(I6<45%,F6*G6*H6*F!$B$43,IF(I6<50%,F6*G6*H6*F!$B$48,IF(I6=50%,F6*G6*H6*F!$B$50,IF(I6=51%,F6*G6*H6*F!$B$51,IF(I6=52%,F6*G6*H6*F!$B$52,IF(I6=53%,F6*G6*H6*F!$B$53,IF(I6=54%,F6*G6*H6*F!$B$54,IF(I6=55%,F6*G6*H6*F!$B$55,IF(I6=56%,F6*G6*H6*F!$B$56,IF(I6=57%,F6*G6*H6*F!$B$57,IF(I6=58%,F6*G6*H6*F!$B$58,IF(I6=59%,F6*G6*H6*F!$B$59,IF(I6=60%,F6*G6*H6*F!$B$60,IF(I6=61%,F6*G6*H6*F!$B$61,IF(I6=62%,F6*G6*H6*F!$B$62,IF(I6=63%,F6*G6*H6*F!$B$63,IF(I6=64%,F6*G6*H6*F!$B$64,IF(I6=65%,F6*G6*H6*F!$B$65,IF(I6=66%,F6*G6*H6*F!$B$66,IF(I6=67%,F6*G6*H6*F!$B$67,IF(I6=68%,F6*G6*H6*F!$B$68,IF(I6=69%,F6*G6*H6*F!$B$69,IF(I6=70%,F6*G6*H6*F!$B$70,IF(I6=71%,F6*G6*H6*F!$B$71,IF(I6=72%,F6*G6*H6*F!$B$72,IF(I6=73%,F6*G6*H6*F!$B$73,IF(I6=74%,F6*G6*H6*F!$B$74,IF(I6=75%,F6*G6*H6*F!$B$75,IF(I6=76%,F6*G6*H6*F!$B$76,IF(I6=77%,F6*G6*H6*F!$B$77,IF(I6=78%,F6*G6*H6*F!$B$78,IF(I6=79%,F6*G6*H6*F!$B$79,IF(I6=80%,F6*G6*H6*F!$B$80,IF(I6=81%,F6*G6*H6*F!$B$81,IF(I6=82%,F6*G6*H6*F!$B$82,IF(I6=83%,F6*G6*H6*F!$B$83,IF(I6=84%,F6*G6*H6*F!$B$84,IF(I6=85%,F6*G6*H6*F!$B$85,IF(I6=86%,F6*G6*H6*F!$B$86,IF(I6=87%,F6*G6*H6*F!$B$87,IF(I6=88%,F6*G6*H6*F!$B$88,IF(I6=89%,F6*G6*H6*F!$B$89,IF(I6=90%,F6*G6*H6*F!$B$90,IF(I6=91%,F6*G6*H6*F!$B$91,IF(I6=92%,F6*G6*H6*F!$B$92,IF(I6=93%,F6*G6*H6*F!$B$93,IF(I6=94%,F6*G6*H6*F!$B$94,IF(I6=95%,F6*G6*H6*F!$B$95,IF(I6=96%,F6*G6*H6*F!$B$96,IF(I6=97%,F6*G6*H6*F!$B$97,IF(I6=98%,F6*G6*H6*F!$B$98,IF(I6=99%,F6*G6*H6*F!$B$99,IF(I6>99%,F6*G6*H6*F!$B$100,))))))))))))))))))))))))))))))))))))))))))))))))))))))))+IF(M6<30%,0,IF(M6<35%,J6*K6*L6*F!$B$33,IF(M6<40%,J6*K6*L6*F!$B$38,IF(M6<45%,J6*K6*L6*F!$B$43,IF(M6<50%,J6*K6*L6*F!$B$48,IF(M6=50%,J6*K6*L6*F!$B$50,IF(M6=51%,J6*K6*L6*F!$B$51,IF(M6=52%,J6*K6*L6*F!$B$52,IF(M6=53%,J6*K6*L6*F!$B$53,IF(M6=54%,J6*K6*L6*F!$B$54,IF(M6=55%,J6*K6*L6*F!$B$55,IF(M6=56%,J6*K6*L6*F!$B$56,IF(M6=57%,J6*K6*L6*F!$B$57,IF(M6=58%,J6*K6*L6*F!$B$58,IF(M6=59%,J6*K6*L6*F!$B$59,IF(M6=60%,J6*K6*L6*F!$B$60,IF(M6=61%,J6*K6*L6*F!$B$61,IF(M6=62%,J6*K6*L6*F!$B$62,IF(M6=63%,J6*K6*L6*F!$B$63,IF(M6=64%,J6*K6*L6*F!$B$64,IF(M6=65%,J6*K6*L6*F!$B$65,IF(M6=66%,J6*K6*L6*F!$B$66,IF(M6=67%,J6*K6*L6*F!$B$67,IF(M6=68%,J6*K6*L6*F!$B$68,IF(M6=69%,J6*K6*L6*F!$B$69,IF(M6=70%,J6*K6*L6*F!$B$70,IF(M6=71%,J6*K6*L6*F!$B$71,IF(M6=72%,J6*K6*L6*F!$B$72,IF(M6=73%,J6*K6*L6*F!$B$73,IF(M6=74%,J6*K6*L6*F!$B$74,IF(M6=75%,J6*K6*L6*F!$B$75,IF(M6=76%,J6*K6*L6*F!$B$76,IF(M6=77%,J6*K6*L6*F!$B$77,IF(M6=78%,J6*K6*L6*F!$B$78,IF(M6=79%,J6*K6*L6*F!$B$79,IF(M6=80%,J6*K6*L6*F!$B$80,IF(M6=81%,J6*K6*L6*F!$B$81,IF(M6=82%,J6*K6*L6*F!$B$82,IF(M6=83%,J6*K6*L6*F!$B$83,IF(M6=84%,J6*K6*L6*F!$B$84,IF(M6=85%,J6*K6*L6*F!$B$85,IF(M6=86%,J6*K6*L6*F!$B$86,IF(M6=87%,J6*K6*L6*F!$B$87,IF(M6=88%,J6*K6*L6*F!$B$88,IF(M6=89%,J6*K6*L6*F!$B$89,IF(M6=90%,J6*K6*L6*F!$B$90,IF(M6=91%,J6*K6*L6*F!$B$91,IF(M6=92%,J6*K6*L6*F!$B$92,IF(M6=93%,J6*K6*L6*F!$B$93,IF(M6=94%,J6*K6*L6*F!$B$94,IF(M6=95%,J6*K6*L6*F!$B$95,IF(M6=96%,J6*K6*L6*F!$B$96,IF(M6=97%,J6*K6*L6*F!$B$97,IF(M6=98%,J6*K6*L6*F!$B$98,IF(M6=99%,J6*K6*L6*F!$B$99,IF(M6>99%,J6*K6*L6*F!$B$100,))))))))))))))))))))))))))))))))))))))))))))))))))))))))+IF(Q6<30%,0,IF(Q6<35%,N6*O6*P6*F!$B$33,IF(Q6<40%,N6*O6*P6*F!$B$38,IF(Q6<45%,N6*O6*P6*F!$B$43,IF(Q6<50%,N6*O6*P6*F!$B$48,IF(Q6=50%,N6*O6*P6*F!$B$50,IF(Q6=51%,N6*O6*P6*F!$B$51,IF(Q6=52%,N6*O6*P6*F!$B$52,IF(Q6=53%,N6*O6*P6*F!$B$53,IF(Q6=54%,N6*O6*P6*F!$B$54,IF(Q6=55%,N6*O6*P6*F!$B$55,IF(Q6=56%,N6*O6*P6*F!$B$56,IF(Q6=57%,N6*O6*P6*F!$B$57,IF(Q6=58%,N6*O6*P6*F!$B$58,IF(Q6=59%,N6*O6*P6*F!$B$59,IF(Q6=60%,N6*O6*P6*F!$B$60,IF(Q6=61%,N6*O6*P6*F!$B$61,IF(Q6=62%,N6*O6*P6*F!$B$62,IF(Q6=63%,N6*O6*P6*F!$B$63,IF(Q6=64%,N6*O6*P6*F!$B$64,IF(Q6=65%,N6*O6*P6*F!$B$65,IF(Q6=66%,N6*O6*P6*F!$B$66,IF(Q6=67%,N6*O6*P6*F!$B$67,IF(Q6=68%,N6*O6*P6*F!$B$68,IF(Q6=69%,N6*O6*P6*F!$B$69,IF(Q6=70%,N6*O6*P6*F!$B$70,IF(Q6=71%,N6*O6*P6*F!$B$71,IF(Q6=72%,N6*O6*P6*F!$B$72,IF(Q6=73%,N6*O6*P6*F!$B$73,IF(Q6=74%,N6*O6*P6*F!$B$74,IF(Q6=75%,N6*O6*P6*F!$B$75,IF(Q6=76%,N6*O6*P6*F!$B$76,IF(Q6=77%,N6*O6*P6*F!$B$77,IF(Q6=78%,N6*O6*P6*F!$B$78,IF(Q6=79%,N6*O6*P6*F!$B$79,IF(Q6=80%,N6*O6*P6*F!$B$80,IF(Q6=81%,N6*O6*P6*F!$B$81,IF(Q6=82%,N6*O6*P6*F!$B$82,IF(Q6=83%,N6*O6*P6*F!$B$83,IF(Q6=84%,N6*O6*P6*F!$B$84,IF(Q6=85%,N6*O6*P6*F!$B$85,IF(Q6=86%,N6*O6*P6*F!$B$86,IF(Q6=87%,N6*O6*P6*F!$B$87,IF(Q6=88%,N6*O6*P6*F!$B$88,IF(Q6=89%,N6*O6*P6*F!$B$89,IF(Q6=90%,N6*O6*P6*F!$B$90,IF(Q6=91%,N6*O6*P6*F!$B$91,IF(Q6=92%,N6*O6*P6*F!$B$92,IF(Q6=93%,N6*O6*P6*F!$B$93,IF(Q6=94%,N6*O6*P6*F!$B$94,IF(Q6=95%,N6*O6*P6*F!$B$95,IF(Q6=96%,N6*O6*P6*F!$B$96,IF(Q6=97%,N6*O6*P6*F!$B$97,IF(Q6=98%,N6*O6*P6*F!$B$98,IF(Q6=99%,N6*O6*P6*F!$B$99,IF(Q6>99%,N6*O6*P6*F!$B$100,))))))))))))))))))))))))))))))))))))))))))))))))))))))))+IF(U6<30%,0,IF(U6<35%,R6*S6*T6*F!$B$33,IF(U6<40%,R6*S6*T6*F!$B$38,IF(U6<45%,R6*S6*T6*F!$B$43,IF(U6<50%,R6*S6*T6*F!$B$48,IF(U6=50%,R6*S6*T6*F!$B$50,IF(U6=51%,R6*S6*T6*F!$B$51,IF(U6=52%,R6*S6*T6*F!$B$52,IF(U6=53%,R6*S6*T6*F!$B$53,IF(U6=54%,R6*S6*T6*F!$B$54,IF(U6=55%,R6*S6*T6*F!$B$55,IF(U6=56%,R6*S6*T6*F!$B$56,IF(U6=57%,R6*S6*T6*F!$B$57,IF(U6=58%,R6*S6*T6*F!$B$58,IF(U6=59%,R6*S6*T6*F!$B$59,IF(U6=60%,R6*S6*T6*F!$B$60,IF(U6=61%,R6*S6*T6*F!$B$61,IF(U6=62%,R6*S6*T6*F!$B$62,IF(U6=63%,R6*S6*T6*F!$B$63,IF(U6=64%,R6*S6*T6*F!$B$64,IF(U6=65%,R6*S6*T6*F!$B$65,IF(U6=66%,R6*S6*T6*F!$B$66,IF(U6=67%,R6*S6*T6*F!$B$67,IF(U6=68%,R6*S6*T6*F!$B$68,IF(U6=69%,R6*S6*T6*F!$B$69,IF(U6=70%,R6*S6*T6*F!$B$70,IF(U6=71%,R6*S6*T6*F!$B$71,IF(U6=72%,R6*S6*T6*F!$B$72,IF(U6=73%,R6*S6*T6*F!$B$73,IF(U6=74%,R6*S6*T6*F!$B$74,IF(U6=75%,R6*S6*T6*F!$B$75,IF(U6=76%,R6*S6*T6*F!$B$76,IF(U6=77%,R6*S6*T6*F!$B$77,IF(U6=78%,R6*S6*T6*F!$B$78,IF(U6=79%,R6*S6*T6*F!$B$79,IF(U6=80%,R6*S6*T6*F!$B$80,IF(U6=81%,R6*S6*T6*F!$B$81,IF(U6=82%,R6*S6*T6*F!$B$82,IF(U6=83%,R6*S6*T6*F!$B$83,IF(U6=84%,R6*S6*T6*F!$B$84,IF(U6=85%,R6*S6*T6*F!$B$85,IF(U6=86%,R6*S6*T6*F!$B$86,IF(U6=87%,R6*S6*T6*F!$B$87,IF(U6=88%,R6*S6*T6*F!$B$88,IF(U6=89%,R6*S6*T6*F!$B$89,IF(U6=90%,R6*S6*T6*F!$B$90,IF(U6=91%,R6*S6*T6*F!$B$91,IF(U6=92%,R6*S6*T6*F!$B$92,IF(U6=93%,R6*S6*T6*F!$B$93,IF(U6=94%,R6*S6*T6*F!$B$94,IF(U6=95%,R6*S6*T6*F!$B$95,IF(U6=96%,R6*S6*T6*F!$B$96,IF(U6=97%,R6*S6*T6*F!$B$97,IF(U6=98%,R6*S6*T6*F!$B$98,IF(U6=99%,R6*S6*T6*F!$B$99,IF(U6>99%,R6*S6*T6*F!$B$100)))))))))))))))))))))))))))))))))))))))))))))))))))))))))*IF(ISNUMBER(E6),E6,1)*IF(ISNUMBER(D6),D6,1) -> #REF! | AA6: =G6*H6+K6*L6+O6*P6+S6*T6 -> 52 | AB6: =(H6*(IF(I6<45%,0.5,IF(I6<55%,0.8,IF(I6<65%,0.9,IF(I6<75%,1,IF(I6<85%,1.1,1.2))))))+L6*(IF(M6<45%,0.5,IF(M6<55%,0.8,IF(M6<65%,0.9,IF(M6<75%,1,IF(M6<85%,1.1,1.2))))))+P6*(IF(Q6<45%,0.5,IF(Q6<55%,0.8,IF(Q6<65%,0.9,IF(Q6<75%,1,IF(Q6<85%,1.1,1.2))))))+T6*(IF(U6<45%,0.5,IF(U6<55%,0.8,IF(U6<65%,0.9,IF(U6<75%,1,IF(U6<85%,1.1,1.2)))))))*IF(D6>=0.8,6,IF(D6<=0.4,1.5,3)) -> 24.6
B7: Легкая | C7: Жим гантелей вверх | D7: 1.2 | E7: 2 | F7: =IF(I7<>0,(IFERROR(IF($Y7>50,MROUND($Y7*I7,2.5),IF($Y7<15,MROUND($Y7*I7,0.1),MROUND($Y7*I7,1))),)),"") -> 2.9 | G7: 10 | H7: 4 | I7: 0.42 | J7: =IF(M7<>0,(IFERROR(IF($Y7>50,MROUND($Y7*M7,2.5),IF($Y7<15,MROUND($Y7*M7,0.1),MROUND($Y7*M7,1))),)),"") | M7: 0 | N7: =IF(Q7<>0,(IFERROR(IF($Y7>50,MROUND($Y7*Q7,2.5),IF($Y7<15,MROUND($Y7*Q7,0.1),MROUND($Y7*Q7,1))),)),"") | Q7: 0 | R7: =IF(U7<>0,(IFERROR(IF($Y7>50,MROUND($Y7*U7,2.5),IF($Y7<15,MROUND($Y7*U7,0.1),MROUND($Y7*U7,1))),)),"") | U7: 0 | V7: =(IF(ISNUMBER(F7),F7,1)*G7*H7+IF(ISNUMBER(J7),J7,1)*K7*L7+IF(ISNUMBER(N7),N7,1)*O7*P7+IF(ISNUMBER(R7),R7,1)*S7*T7)*IF(ISNUMBER(E7),E7,1) -> 232 | W7: =IFERROR((IF(ISNUMBER(F7),F7,1)*G7*H7+IF(ISNUMBER(J7),J7,1)*K7*L7+IF(ISNUMBER(N7),N7,1)*O7*P7+IF(ISNUMBER(R7),R7,1)*S7*T7)*IF(ISNUMBER(E7),E7,1)/(G7*H7+K7*L7+O7*P7+S7*T7),0) -> 5.8 | X7: =ROUND(IFERROR((W7/(Y7*IF(ISNUMBER(E7),E7,1))),0),2) -> 0.41 | Y7: 7 | Z7: =(IF(I7<30%,0,IF(I7<35%,F7*G7*H7*F!$B$33,IF(I7<40%,F7*G7*H7*F!$B$38,IF(I7<45%,F7*G7*H7*F!$B$43,IF(I7<50%,F7*G7*H7*F!$B$48,IF(I7=50%,F7*G7*H7*F!$B$50,IF(I7=51%,F7*G7*H7*F!$B$51,IF(I7=52%,F7*G7*H7*F!$B$52,IF(I7=53%,F7*G7*H7*F!$B$53,IF(I7=54%,F7*G7*H7*F!$B$54,IF(I7=55%,F7*G7*H7*F!$B$55,IF(I7=56%,F7*G7*H7*F!$B$56,IF(I7=57%,F7*G7*H7*F!$B$57,IF(I7=58%,F7*G7*H7*F!$B$58,IF(I7=59%,F7*G7*H7*F!$B$59,IF(I7=60%,F7*G7*H7*F!$B$60,IF(I7=61%,F7*G7*H7*F!$B$61,IF(I7=62%,F7*G7*H7*F!$B$62,IF(I7=63%,F7*G7*H7*F!$B$63,IF(I7=64%,F7*G7*H7*F!$B$64,IF(I7=65%,F7*G7*H7*F!$B$65,IF(I7=66%,F7*G7*H7*F!$B$66,IF(I7=67%,F7*G7*H7*F!$B$67,IF(I7=68%,F7*G7*H7*F!$B$68,IF(I7=69%,F7*G7*H7*F!$B$69,IF(I7=70%,F7*G7*H7*F!$B$70,IF(I7=71%,F7*G7*H7*F!$B$71,IF(I7=72%,F7*G7*H7*F!$B$72,IF(I7=73%,F7*G7*H7*F!$B$73,IF(I7=74%,F7*G7*H7*F!$B$74,IF(I7=75%,F7*G7*H7*F!$B$75,IF(I7=76%,F7*G7*H7*F!$B$76,IF(I7=77%,F7*G7*H7*F!$B$77,IF(I7=78%,F7*G7*H7*F!$B$78,IF(I7=79%,F7*G7*H7*F!$B$79,IF(I7=80%,F7*G7*H7*F!$B$80,IF(I7=81%,F7*G7*H7*F!$B$81,IF(I7=82%,F7*G7*H7*F!$B$82,IF(I7=83%,F7*G7*H7*F!$B$83,IF(I7=84%,F7*G7*H7*F!$B$84,IF(I7=85%,F7*G7*H7*F!$B$85,IF(I7=86%,F7*G7*H7*F!$B$86,IF(I7=87%,F7*G7*H7*F!$B$87,IF(I7=88%,F7*G7*H7*F!$B$88,IF(I7=89%,F7*G7*H7*F!$B$89,IF(I7=90%,F7*G7*H7*F!$B$90,IF(I7=91%,F7*G7*H7*F!$B$91,IF(I7=92%,F7*G7*H7*F!$B$92,IF(I7=93%,F7*G7*H7*F!$B$93,IF(I7=94%,F7*G7*H7*F!$B$94,IF(I7=95%,F7*G7*H7*F!$B$95,IF(I7=96%,F7*G7*H7*F!$B$96,IF(I7=97%,F7*G7*H7*F!$B$97,IF(I7=98%,F7*G7*H7*F!$B$98,IF(I7=99%,F7*G7*H7*F!$B$99,IF(I7>99%,F7*G7*H7*F!$B$100,))))))))))))))))))))))))))))))))))))))))))))))))))))))))+IF(M7<30%,0,IF(M7<35%,J7*K7*L7*F!$B$33,IF(M7<40%,J7*K7*L7*F!$B$38,IF(M7<45%,J7*K7*L7*F!$B$43,IF(M7<50%,J7*K7*L7*F!$B$48,IF(M7=50%,J7*K7*L7*F!$B$50,IF(M7=51%,J7*K7*L7*F!$B$51,IF(M7=52%,J7*K7*L7*F!$B$52,IF(M7=53%,J7*K7*L7*F!$B$53,IF(M7=54%,J7*K7*L7*F!$B$54,IF(M7=55%,J7*K7*L7*F!$B$55,IF(M7=56%,J7*K7*L7*F!$B$56,IF(M7=57%,J7*K7*L7*F!$B$57,IF(M7=58%,J7*K7*L7*F!$B$58,IF(M7=59%,J7*K7*L7*F!$B$59,IF(M7=60%,J7*K7*L7*F!$B$60,IF(M7=61%,J7*K7*L7*F!$B$61,IF(M7=62%,J7*K7*L7*F!$B$62,IF(M7=63%,J7*K7*L7*F!$B$63,IF(M7=64%,J7*K7*L7*F!$B$64,IF(M7=65%,J7*K7*L7*F!$B$65,IF(M7=66%,J7*K7*L7*F!$B$66,IF(M7=67%,J7*K7*L7*F!$B$67,IF(M7=68%,J7*K7*L7*F!$B$68,IF(M7=69%,J7*K7*L7*F!$B$69,IF(M7=70%,J7*K7*L7*F!$B$70,IF(M7=71%,J7*K7*L7*F!$B$71,IF(M7=72%,J7*K7*L7*F!$B$72,IF(M7=73%,J7*K7*L7*F!$B$73,IF(M7=74%,J7*K7*L7*F!$B$74,IF(M7=75%,J7*K7*L7*F!$B$75,IF(M7=76%,J7*K7*L7*F!$B$76,IF(M7=77%,J7*K7*L7*F!$B$77,IF(M7=78%,J7*K7*L7*F!$B$78,IF(M7=79%,J7*K7*L7*F!$B$79,IF(M7=80%,J7*K7*L7*F!$B$80,IF(M7=81%,J7*K7*L7*F!$B$81,IF(M7=82%,J7*K7*L7*F!$B$82,IF(M7=83%,J7*K7*L7*F!$B$83,IF(M7=84%,J7*K7*L7*F!$B$84,IF(M7=85%,J7*K7*L7*F!$B$85,IF(M7=86%,J7*K7*L7*F!$B$86,IF(M7=87%,J7*K7*L7*F!$B$87,IF(M7=88%,J7*K7*L7*F!$B$88,IF(M7=89%,J7*K7*L7*F!$B$89,IF(M7=90%,J7*K7*L7*F!$B$90,IF(M7=91%,J7*K7*L7*F!$B$91,IF(M7=92%,J7*K7*L7*F!$B$92,IF(M7=93%,J7*K7*L7*F!$B$93,IF(M7=94%,J7*K7*L7*F!$B$94,IF(M7=95%,J7*K7*L7*F!$B$95,IF(M7=96%,J7*K7*L7*F!$B$96,IF(M7=97%,J7*K7*L7*F!$B$97,IF(M7=98%,J7*K7*L7*F!$B$98,IF(M7=99%,J7*K7*L7*F!$B$99,IF(M7>99%,J7*K7*L7*F!$B$100,))))))))))))))))))))))))))))))))))))))))))))))))))))))))+IF(Q7<30%,0,IF(Q7<35%,N7*O7*P7*F!$B$33,IF(Q7<40%,N7*O7*P7*F!$B$38,IF(Q7<45%,N7*O7*P7*F!$B$43,IF(Q7<50%,N7*O7*P7*F!$B$48,IF(Q7=50%,N7*O7*P7*F!$B$50,IF(Q7=51%,N7*O7*P7*F!$B$51,IF(Q7=52%,N7*O7*P7*F!$B$52,IF(Q7=53%,N7*O7*P7*F!$B$53,IF(Q7=54%,N7*O7*P7*F!$B$54,IF(Q7=55%,N7*O7*P7*F!$B$55,IF(Q7=56%,N7*O7*P7*F!$B$56,IF(Q7=57%,N7*O7*P7*F!$B$57,IF(Q7=58%,N7*O7*P7*F!$B$58,IF(Q7=59%,N7*O7*P7*F!$B$59,IF(Q7=60%,N7*O7*P7*F!$B$60,IF(Q7=61%,N7*O7*P7*F!$B$61,IF(Q7=62%,N7*O7*P7*F!$B$62,IF(Q7=63%,N7*O7*P7*F!$B$63,IF(Q7=64%,N7*O7*P7*F!$B$64,IF(Q7=65%,N7*O7*P7*F!$B$65,IF(Q7=66%,N7*O7*P7*F!$B$66,IF(Q7=67%,N7*O7*P7*F!$B$67,IF(Q7=68%,N7*O7*P7*F!$B$68,IF(Q7=69%,N7*O7*P7*F!$B$69,IF(Q7=70%,N7*O7*P7*F!$B$70,IF(Q7=71%,N7*O7*P7*F!$B$71,IF(Q7=72%,N7*O7*P7*F!$B$72,IF(Q7=73%,N7*O7*P7*F!$B$73,IF(Q7=74%,N7*O7*P7*F!$B$74,IF(Q7=75%,N7*O7*P7*F!$B$75,IF(Q7=76%,N7*O7*P7*F!$B$76,IF(Q7=77%,N7*O7*P7*F!$B$77,IF(Q7=78%,N7*O7*P7*F!$B$78,IF(Q7=79%,N7*O7*P7*F!$B$79,IF(Q7=80%,N7*O7*P7*F!$B$80,IF(Q7=81%,N7*O7*P7*F!$B$81,IF(Q7=82%,N7*O7*P7*F!$B$82,IF(Q7=83%,N7*O7*P7*F!$B$83,IF(Q7=84%,N7*O7*P7*F!$B$84,IF(Q7=85%,N7*O7*P7*F!$B$85,IF(Q7=86%,N7*O7*P7*F!$B$86,IF(Q7=87%,N7*O7*P7*F!$B$87,IF(Q7=88%,N7*O7*P7*F!$B$88,IF(Q7=89%,N7*O7*P7*F!$B$89,IF(Q7=90%,N7*O7*P7*F!$B$90,IF(Q7=91%,N7*O7*P7*F!$B$91,IF(Q7=92%,N7*O7*P7*F!$B$92,IF(Q7=93%,N7*O7*P7*F!$B$93,IF(Q7=94%,N7*O7*P7*F!$B$94,IF(Q7=95%,N7*O7*P7*F!$B$95,IF(Q7=96%,N7*O7*P7*F!$B$96,IF(Q7=97%,N7*O7*P7*F!$B$97,IF(Q7=98%,N7*O7*P7*F!$B$98,IF(Q7=99%,N7*O7*P7*F!$B$99,IF(Q7>99%,N7*O7*P7*F!$B$100,))))))))))))))))))))))))))))))))))))))))))))))))))))))))+IF(U7<30%,0,IF(U7<35%,R7*S7*T7*F!$B$33,IF(U7<40%,R7*S7*T7*F!$B$38,IF(U7<45%,R7*S7*T7*F!$B$43,IF(U7<50%,R7*S7*T7*F!$B$48,IF(U7=50%,R7*S7*T7*F!$B$50,IF(U7=51%,R7*S7*T7*F!$B$51,IF(U7=52%,R7*S7*T7*F!$B$52,IF(U7=53%,R7*S7*T7*F!$B$53,IF(U7=54%,R7*S7*T7*F!$B$54,IF(U7=55%,R7*S7*T7*F!$B$55,IF(U7=56%,R7*S7*T7*F!$B$56,IF(U7=57%,R7*S7*T7*F!$B$57,IF(U7=58%,R7*S7*T7*F!$B$58,IF(U7=59%,R7*S7*T7*F!$B$59,IF(U7=60%,R7*S7*T7*F!$B$60,IF(U7=61%,R7*S7*T7*F!$B$61,IF(U7=62%,R7*S7*T7*F!$B$62,IF(U7=63%,R7*S7*T7*F!$B$63,IF(U7=64%,R7*S7*T7*F!$B$64,IF(U7=65%,R7*S7*T7*F!$B$65,IF(U7=66%,R7*S7*T7*F!$B$66,IF(U7=67%,R7*S7*T7*F!$B$67,IF(U7=68%,R7*S7*T7*F!$B$68,IF(U7=69%,R7*S7*T7*F!$B$69,IF(U7=70%,R7*S7*T7*F!$B$70,IF(U7=71%,R7*S7*T7*F!$B$71,IF(U7=72%,R7*S7*T7*F!$B$72,IF(U7=73%,R7*S7*T7*F!$B$73,IF(U7=74%,R7*S7*T7*F!$B$74,IF(U7=75%,R7*S7*T7*F!$B$75,IF(U7=76%,R7*S7*T7*F!$B$76,IF(U7=77%,R7*S7*T7*F!$B$77,IF(U7=78%,R7*S7*T7*F!$B$78,IF(U7=79%,R7*S7*T7*F!$B$79,IF(U7=80%,R7*S7*T7*F!$B$80,IF(U7=81%,R7*S7*T7*F!$B$81,IF(U7=82%,R7*S7*T7*F!$B$82,IF(U7=83%,R7*S7*T7*F!$B$83,IF(U7=84%,R7*S7*T7*F!$B$84,IF(U7=85%,R7*S7*T7*F!$B$85,IF(U7=86%,R7*S7*T7*F!$B$86,IF(U7=87%,R7*S7*T7*F!$B$87,IF(U7=88%,R7*S7*T7*F!$B$88,IF(U7=89%,R7*S7*T7*F!$B$89,IF(U7=90%,R7*S7*T7*F!$B$90,IF(U7=91%,R7*S7*T7*F!$B$91,IF(U7=92%,R7*S7*T7*F!$B$92,IF(U7=93%,R7*S7*T7*F!$B$93,IF(U7=94%,R7*S7*T7*F!$B$94,IF(U7=95%,R7*S7*T7*F!$B$95,IF(U7=96%,R7*S7*T7*F!$B$96,IF(U7=97%,R7*S7*T7*F!$B$97,IF(U7=98%,R7*S7*T7*F!$B$98,IF(U7=99%,R7*S7*T7*F!$B$99,IF(U7>99%,R7*S7*T7*F!$B$100)))))))))))))))))))))))))))))))))))))))))))))))))))))))))*IF(ISNUMBER(E7),E7,1)*IF(ISNUMBER(D7),D7,1) -> #REF! | AA7: =G7*H7+K7*L7+O7*P7+S7*T7 -> 40 | AB7: =(H7*(IF(I7<45%,0.5,IF(I7<55%,0.8,IF(I7<65%,0.9,IF(I7<75%,1,IF(I7<85%,1.1,1.2))))))+L7*(IF(M7<45%,0.5,IF(M7<55%,0.8,IF(M7<65%,0.9,IF(M7<75%,1,IF(M7<85%,1.1,1.2))))))+P7*(IF(Q7<45%,0.5,IF(Q7<55%,0.8,IF(Q7<65%,0.9,IF(Q7<75%,1,IF(Q7<85%,1.1,1.2))))))+T7*(IF(U7<45%,0.5,IF(U7<55%,0.8,IF(U7<65%,0.9,IF(U7<75%,1,IF(U7<85%,1.1,1.2)))))))*IF(D7>=0.8,6,IF(D7<=0.4,1.5,3)) -> 12
B8: Средняя | C8: Разведение гантелей в стороны | D8: 0.4 | E8: 2 | F8: =IF(I8<>0,(IFERROR(IF($Y8>50,MROUND($Y8*I8,2.5),IF($Y8<15,MROUND($Y8*I8,0.1),MROUND($Y8*I8,1))),)),"") -> 2.4 | G8: 12 | H8: 1 | I8: 0.4 | J8: =IF(M8<>0,(IFERROR(IF($Y8>50,MROUND($Y8*M8,2.5),IF($Y8<15,MROUND($Y8*M8,0.1),MROUND($Y8*M8,1))),)),"") -> 3.3 | K8: 12 | L8: 3 | M8: 0.55 | N8: =IF(Q8<>0,(IFERROR(IF($Y8>50,MROUND($Y8*Q8,2.5),IF($Y8<15,MROUND($Y8*Q8,0.1),MROUND($Y8*Q8,1))),)),"") | Q8: 0 | R8: =IF(U8<>0,(IFERROR(IF($Y8>50,MROUND($Y8*U8,2.5),IF($Y8<15,MROUND($Y8*U8,0.1),MROUND($Y8*U8,1))),)),"") | U8: 0 | V8: =(IF(ISNUMBER(F8),F8,1)*G8*H8+IF(ISNUMBER(J8),J8,1)*K8*L8+IF(ISNUMBER(N8),N8,1)*O8*P8+IF(ISNUMBER(R8),R8,1)*S8*T8)*IF(ISNUMBER(E8),E8,1) -> 295.2 | W8: =IFERROR((IF(ISNUMBER(F8),F8,1)*G8*H8+IF(ISNUMBER(J8),J8,1)*K8*L8+IF(ISNUMBER(N8),N8,1)*O8*P8+IF(ISNUMBER(R8),R8,1)*S8*T8)*IF(ISNUMBER(E8),E8,1)/(G8*H8+K8*L8+O8*P8+S8*T8),0) -> 6.15 | X8: =ROUND(IFERROR((W8/(Y8*IF(ISNUMBER(E8),E8,1))),0),2) -> 0.51 | Y8: 6 | Z8: =(IF(I8<30%,0,IF(I8<35%,F8*G8*H8*F!$B$33,IF(I8<40%,F8*G8*H8*F!$B$38,IF(I8<45%,F8*G8*H8*F!$B$43,IF(I8<50%,F8*G8*H8*F!$B$48,IF(I8=50%,F8*G8*H8*F!$B$50,IF(I8=51%,F8*G8*H8*F!$B$51,IF(I8=52%,F8*G8*H8*F!$B$52,IF(I8=53%,F8*G8*H8*F!$B$53,IF(I8=54%,F8*G8*H8*F!$B$54,IF(I8=55%,F8*G8*H8*F!$B$55,IF(I8=56%,F8*G8*H8*F!$B$56,IF(I8=57%,F8*G8*H8*F!$B$57,IF(I8=58%,F8*G8*H8*F!$B$58,IF(I8=59%,F8*G8*H8*F!$B$59,IF(I8=60%,F8*G8*H8*F!$B$60,IF(I8=61%,F8*G8*H8*F!$B$61,IF(I8=62%,F8*G8*H8*F!$B$62,IF(I8=63%,F8*G8*H8*F!$B$63,IF(I8=64%,F8*G8*H8*F!$B$64,IF(I8=65%,F8*G8*H8*F!$B$65,IF(I8=66%,F8*G8*H8*F!$B$66,IF(I8=67%,F8*G8*H8*F!$B$67,IF(I8=68%,F8*G8*H8*F!$B$68,IF(I8=69%,F8*G8*H8*F!$B$69,IF(I8=70%,F8*G8*H8*F!$B$70,IF(I8=71%,F8*G8*H8*F!$B$71,IF(I8=72%,F8*G8*H8*F!$B$72,IF(I8=73%,F8*G8*H8*F!$B$73,IF(I8=74%,F8*G8*H8*F!$B$74,IF(I8=75%,F8*G8*H8*F!$B$75,IF(I8=76%,F8*G8*H8*F!$B$76,IF(I8=77%,F8*G8*H8*F!$B$77,IF(I8=78%,F8*G8*H8*F!$B$78,IF(I8=79%,F8*G8*H8*F!$B$79,IF(I8=80%,F8*G8*H8*F!$B$80,IF(I8=81%,F8*G8*H8*F!$B$81,IF(I8=82%,F8*G8*H8*F!$B$82,IF(I8=83%,F8*G8*H8*F!$B$83,IF(I8=84%,F8*G8*H8*F!$B$84,IF(I8=85%,F8*G8*H8*F!$B$85,IF(I8=86%,F8*G8*H8*F!$B$86,IF(I8=87%,F8*G8*H8*F!$B$87,IF(I8=88%,F8*G8*H8*F!$B$88,IF(I8=89%,F8*G8*H8*F!$B$89,IF(I8=90%,F8*G8*H8*F!$B$90,IF(I8=91%,F8*G8*H8*F!$B$91,IF(I8=92%,F8*G8*H8*F!$B$92,IF(I8=93%,F8*G8*H8*F!$B$93,IF(I8=94%,F8*G8*H8*F!$B$94,IF(I8=95%,F8*G8*H8*F!$B$95,IF(I8=96%,F8*G8*H8*F!$B$96,IF(I8=97%,F8*G8*H8*F!$B$97,IF(I8=98%,F8*G8*H8*F!$B$98,IF(I8=99%,F8*G8*H8*F!$B$99,IF(I8>99%,F8*G8*H8*F!$B$100,))))))))))))))))))))))))))))))))))))))))))))))))))))))))+IF(M8<30%,0,IF(M8<35%,J8*K8*L8*F!$B$33,IF(M8<40%,J8*K8*L8*F!$B$38,IF(M8<45%,J8*K8*L8*F!$B$43,IF(M8<50%,J8*K8*L8*F!$B$48,IF(M8=50%,J8*K8*L8*F!$B$50,IF(M8=51%,J8*K8*L8*F!$B$51,IF(M8=52%,J8*K8*L8*F!$B$52,IF(M8=53%,J8*K8*L8*F!$B$53,IF(M8=54%,J8*K8*L8*F!$B$54,IF(M8=55%,J8*K8*L8*F!$B$55,IF(M8=56%,J8*K8*L8*F!$B$56,IF(M8=57%,J8*K8*L8*F!$B$57,IF(M8=58%,J8*K8*L8*F!$B$58,IF(M8=59%,J8*K8*L8*F!$B$59,IF(M8=60%,J8*K8*L8*F!$B$60,IF(M8=61%,J8*K8*L8*F!$B$61,IF(M8=62%,J8*K8*L8*F!$B$62,IF(M8=63%,J8*K8*L8*F!$B$63,IF(M8=64%,J8*K8*L8*F!$B$64,IF(M8=65%,J8*K8*L8*F!$B$65,IF(M8=66%,J8*K8*L8*F!$B$66,IF(M8=67%,J8*K8*L8*F!$B$67,IF(M8=68%,J8*K8*L8*F!$B$68,IF(M8=69%,J8*K8*L8*F!$B$69,IF(M8=70%,J8*K8*L8*F!$B$70,IF(M8=71%,J8*K8*L8*F!$B$71,IF(M8=72%,J8*K8*L8*F!$B$72,IF(M8=73%,J8*K8*L8*F!$B$73,IF(M8=74%,J8*K8*L8*F!$B$74,IF(M8=75%,J8*K8*L8*F!$B$75,IF(M8=76%,J8*K8*L8*F!$B$76,IF(M8=77%,J8*K8*L8*F!$B$77,IF(M8=78%,J8*K8*L8*F!$B$78,IF(M8=79%,J8*K8*L8*F!$B$79,IF(M8=80%,J8*K8*L8*F!$B$80,IF(M8=81%,J8*K8*L8*F!$B$81,IF(M8=82%,J8*K8*L8*F!$B$82,IF(M8=83%,J8*K8*L8*F!$B$83,IF(M8=84%,J8*K8*L8*F!$B$84,IF(M8=85%,J8*K8*L8*F!$B$85,IF(M8=86%,J8*K8*L8*F!$B$86,IF(M8=87%,J8*K8*L8*F!$B$87,IF(M8=88%,J8*K8*L8*F!$B$88,IF(M8=89%,J8*K8*L8*F!$B$89,IF(M8=90%,J8*K8*L8*F!$B$90,IF(M8=91%,J8*K8*L8*F!$B$91,IF(M8=92%,J8*K8*L8*F!$B$92,IF(M8=93%,J8*K8*L8*F!$B$93,IF(M8=94%,J8*K8*L8*F!$B$94,IF(M8=95%,J8*K8*L8*F!$B$95,IF(M8=96%,J8*K8*L8*F!$B$96,IF(M8=97%,J8*K8*L8*F!$B$97,IF(M8=98%,J8*K8*L8*F!$B$98,IF(M8=99%,J8*K8*L8*F!$B$99,IF(M8>99%,J8*K8*L8*F!$B$100,))))))))))))))))))))))))))))))))))))))))))))))))))))))))+IF(Q8<30%,0,IF(Q8<35%,N8*O8*P8*F!$B$33,IF(Q8<40%,N8*O8*P8*F!$B$38,IF(Q8<45%,N8*O8*P8*F!$B$43,IF(Q8<50%,N8*O8*P8*F!$B$48,IF(Q8=50%,N8*O8*P8*F!$B$50,IF(Q8=51%,N8*O8*P8*F!$B$51,IF(Q8=52%,N8*O8*P8*F!$B$52,IF(Q8=53%,N8*O8*P8*F!$B$53,IF(Q8=54%,N8*O8*P8*F!$B$54,IF(Q8=55%,N8*O8*P8*F!$B$55,IF(Q8=56%,N8*O8*P8*F!$B$56,IF(Q8=57%,N8*O8*P8*F!$B$57,IF(Q8=58%,N8*O8*P8*F!$B$58,IF(Q8=59%,N8*O8*P8*F!$B$59,IF(Q8=60%,N8*O8*P8*F!$B$60,IF(Q8=61%,N8*O8*P8*F!$B$61,IF(Q8=62%,N8*O8*P8*F!$B$62,IF(Q8=63%,N8*O8*P8*F!$B$63,IF(Q8=64%,N8*O8*P8*F!$B$64,IF(Q8=65%,N8*O8*P8*F!$B$65,IF(Q8=66%,N8*O8*P8*F!$B$66,IF(Q8=67%,N8*O8*P8*F!$B$67,IF(Q8=68%,N8*O8*P8*F!$B$68,IF(Q8=69%,N8*O8*P8*F!$B$69,IF(Q8=70%,N8*O8*P8*F!$B$70,IF(Q8=71%,N8*O8*P8*F!$B$71,IF(Q8=72%,N8*O8*P8*F!$B$72,IF(Q8=73%,N8*O8*P8*F!$B$73,IF(Q8=74%,N8*O8*P8*F!$B$74,IF(Q8=75%,N8*O8*P8*F!$B$75,IF(Q8=76%,N8*O8*P8*F!$B$76,IF(Q8=77%,N8*O8*P8*F!$B$77,IF(Q8=78%,N8*O8*P8*F!$B$78,IF(Q8=79%,N8*O8*P8*F!$B$79,IF(Q8=80%,N8*O8*P8*F!$B$80,IF(Q8=81%,N8*O8*P8*F!$B$81,IF(Q8=82%,N8*O8*P8*F!$B$82,IF(Q8=83%,N8*O8*P8*F!$B$83,IF(Q8=84%,N8*O8*P8*F!$B$84,IF(Q8=85%,N8*O8*P8*F!$B$85,IF(Q8=86%,N8*O8*P8*F!$B$86,IF(Q8=87%,N8*O8*P8*F!$B$87,IF(Q8=88%,N8*O8*P8*F!$B$88,IF(Q8=89%,N8*O8*P8*F!$B$89,IF(Q8=90%,N8*O8*P8*F!$B$90,IF(Q8=91%,N8*O8*P8*F!$B$91,IF(Q8=92%,N8*O8*P8*F!$B$92,IF(Q8=93%,N8*O8*P8*F!$B$93,IF(Q8=94%,N8*O8*P8*F!$B$94,IF(Q8=95%,N8*O8*P8*F!$B$95,IF(Q8=96%,N8*O8*P8*F!$B$96,IF(Q8=97%,N8*O8*P8*F!$B$97,IF(Q8=98%,N8*O8*P8*F!$B$98,IF(Q8=99%,N8*O8*P8*F!$B$99,IF(Q8>99%,N8*O8*P8*F!$B$100,))))))))))))))))))))))))))))))))))))))))))))))))))))))))+IF(U8<30%,0,IF(U8<35%,R8*S8*T8*F!$B$33,IF(U8<40%,R8*S8*T8*F!$B$38,IF(U8<45%,R8*S8*T8*F!$B$43,IF(U8<50%,R8*S8*T8*F!$B$48,IF(U8=50%,R8*S8*T8*F!$B$50,IF(U8=51%,R8*S8*T8*F!$B$51,IF(U8=52%,R8*S8*T8*F!$B$52,IF(U8=53%,R8*S8*T8*F!$B$53,IF(U8=54%,R8*S8*T8*F!$B$54,IF(U8=55%,R8*S8*T8*F!$B$55,IF(U8=56%,R8*S8*T8*F!$B$56,IF(U8=57%,R8*S8*T8*F!$B$57,IF(U8=58%,R8*S8*T8*F!$B$58,IF(U8=59%,R8*S8*T8*F!$B$59,IF(U8=60%,R8*S8*T8*F!$B$60,IF(U8=61%,R8*S8*T8*F!$B$61,IF(U8=62%,R8*S8*T8*F!$B$62,IF(U8=63%,R8*S8*T8*F!$B$63,IF(U8=64%,R8*S8*T8*F!$B$64,IF(U8=65%,R8*S8*T8*F!$B$65,IF(U8=66%,R8*S8*T8*F!$B$66,IF(U8=67%,R8*S8*T8*F!$B$67,IF(U8=68%,R8*S8*T8*F!$B$68,IF(U8=69%,R8*S8*T8*F!$B$69,IF(U8=70%,R8*S8*T8*F!$B$70,IF(U8=71%,R8*S8*T8*F!$B$71,IF(U8=72%,R8*S8*T8*F!$B$72,IF(U8=73%,R8*S8*T8*F!$B$73,IF(U8=74%,R8*S8*T8*F!$B$74,IF(U8=75%,R8*S8*T8*F!$B$75,IF(U8=76%,R8*S8*T8*F!$B$76,IF(U8=77%,R8*S8*T8*F!$B$77,IF(U8=78%,R8*S8*T8*F!$B$78,IF(U8=79%,R8*S8*T8*F!$B$79,IF(U8=80%,R8*S8*T8*F!$B$80,IF(U8=81%,R8*S8*T8*F!$B$81,IF(U8=82%,R8*S8*T8*F!$B$82,IF(U8=83%,R8*S8*T8*F!$B$83,IF(U8=84%,R8*S8*T8*F!$B$84,IF(U8=85%,R8*S8*T8*F!$B$85,IF(U8=86%,R8*S8*T8*F!$B$86,IF(U8=87%,R8*S8*T8*F!$B$87,IF(U8=88%,R8*S8*T8*F!$B$88,IF(U8=89%,R8*S8*T8*F!$B$89,IF(U8=90%,R8*S8*T8*F!$B$90,IF(U8=91%,R8*S8*T8*F!$B$91,IF(U8=92%,R8*S8*T8*F!$B$92,IF(U8=93%,R8*S8*T8*F!$B$93,IF(U8=94%,R8*S8*T8*F!$B$94,IF(U8=95%,R8*S8*T8*F!$B$95,IF(U8=96%,R8*S8*T8*F!$B$96,IF(U8=97%,R8*S8*T8*F!$B$97,IF(U8=98%,R8*S8*T8*F!$B$98,IF(U8=99%,R8*S8*T8*F!$B$99,IF(U8>99%,R8*S8*T8*F!$B$100)))))))))))))))))))))))))))))))))))))))))))))))))))))))))*IF(ISNUMBER(E8),E8,1)*IF(ISNUMBER(D8),D8,1) -> #REF! | AA8: =G8*H8+K8*L8+O8*P8+S8*T8 -> 48 | AB8: =(H8*(IF(I8<45%,0.5,IF(I8<55%,0.8,IF(I8<65%,0.9,IF(I8<75%,1,IF(I8<85%,1.1,1.2))))))+L8*(IF(M8<45%,0.5,IF(M8<55%,0.8,IF(M8<65%,0.9,IF(M8<75%,1,IF(M8<85%,1.1,1.2))))))+P8*(IF(Q8<45%,0.5,IF(Q8<55%,0.8,IF(Q8<65%,0.9,IF(Q8<75%,1,IF(Q8<85%,1.1,1.2))))))+T8*(IF(U8<45%,0.5,IF(U8<55%,0.8,IF(U8<65%,0.9,IF(U8<75%,1,IF(U8<85%,1.1,1.2)))))))*IF(D8>=0.8,6,IF(D8<=0.4,1.5,3)) -> 4.8
C9: Разгибание рук на блоке | D9: =ROUND(IFERROR((D3*(G3*H3+K3*L3+O3*P3+S3*T3)+D4*(G4*H4+K4*L4+O4*P4+S4*T4)+D5*(G5*H5+K5*L5+O5*P5+S5*T5)+D6*(G6*H6+K6*L6+O6*P6+S6*T6)+D7*(G7*H7+K7*L7+O7*P7+S7*T7)+D8*(G8*H8+K8*L8+O8*P8+S8*T8))/((G3*H3+K3*L3+O3*P3+S3*T3)+(G4*H4+K4*L4+O4*P4+S4*T4)+(G5*H5+K5*L5+O5*P5+S5*T5)+(G6*H6+K6*L6+O6*P6+S6*T6)+(G7*H7+K7*L7+O7*P7+S7*T7)+(G8*H8+K8*L8+O8*P8+S8*T8)),0),2) -> 0.76 | V9: =SUM(V3:V8) -> 5453.2 | W9: =IFERROR(V9/AA9,0) -> 20.500752 | X9: =ROUND(IFERROR(((I3*G3*H3+M3*K3*L3+Q3*O3*P3+U3*S3*T3)+(I4*G4*H4+M4*K4*L4+Q4*O4*P4+U4*S4*T4)+(I5*G5*H5+M5*K5*L5+Q5*O5*P5+U5*S5*T5)+(I6*G6*H6+M6*K6*L6+Q6*O6*P6+U6*S6*T6)+(I7*G7*H7+M7*K7*L7+Q7*O7*P7+U7*S7*T7)+(I8*G8*H8+M8*K8*L8+Q8*O8*P8+U8*S8*T8))/((G3*H3+K3*L3+O3*P3+S3*T3)+(G4*H4+K4*L4+O4*P4+S4*T4)+(G5*H5+K5*L5+O5*P5+S5*T5)+(G6*H6+K6*L6+O6*P6+S6*T6)+(G7*H7+K7*L7+O7*P7+S7*T7)+(G8*H8+K8*L8+O8*P8+S8*T8)),0),3) -> 0.479 | Z9: =SUM(Z3:Z8) -> #REF! | AA9: =SUM(AA3:AA8) -> 266 | AB9: =IF(SUM(AB3:AB8)=0,TIME(,0,),TIME(,SUM(AB3:AB8)+30,)) -> 0.070138889
A10: Ср | B10: Средняя | C10: Румынская тяга | D10: 1 | F10: =IF(I10<>0,(IFERROR(IF($Y10>50,MROUND($Y10*I10,2.5),IF($Y10<15,MROUND($Y10*I10,0.1),MROUND($Y10*I10,1))),)),"") -> 22.5 | G10: 12 | H10: 1 | I10: 0.4 | J10: =IF(M10<>0,(IFERROR(IF($Y10>50,MROUND($Y10*M10,2.5),IF($Y10<15,MROUND($Y10*M10,0.1),MROUND($Y10*M10,1))),)),"") -> 32.5 | K10: 10 | L10: 4 | M10: 0.6 | N10: =IF(Q10<>0,(IFERROR(IF($Y10>50,MROUND($Y10*Q10,2.5),IF($Y10<15,MROUND($Y10*Q10,0.1),MROUND($Y10*Q10,1))),)),"") | Q10: 0 | R10: =IF(U10<>0,(IFERROR(IF($Y10>50,MROUND($Y10*U10,2.5),IF($Y10<15,MROUND($Y10*U10,0.1),MROUND($Y10*U10,1))),)),"") | U10: 0 | V10: =(IF(ISNUMBER(F10),F10,1)*G10*H10+IF(ISNUMBER(J10),J10,1)*K10*L10+IF(ISNUMBER(N10),N10,1)*O10*P10+IF(ISNUMBER(R10),R10,1)*S10*T10)*IF(ISNUMBER(E10),E10,1) -> 1570 | W10: =IFERROR((IF(ISNUMBER(F10),F10,1)*G10*H10+IF(ISNUMBER(J10),J10,1)*K10*L10+IF(ISNUMBER(N10),N10,1)*O10*P10+IF(ISNUMBER(R10),R10,1)*S10*T10)*IF(ISNUMBER(E10),E10,1)/(G10*H10+K10*L10+O10*P10+S10*T10),0) -> 30.192308 | X10: =ROUND(IFERROR((W10/(Y10*IF(ISNUMBER(E10),E10,1))),0),2) -> 0.55 | Y10: 55 | Z10: =(IF(I10<30%,0,IF(I10<35%,F10*G10*H10*F!$B$33,IF(I10<40%,F10*G10*H10*F!$B$38,IF(I10<45%,F10*G10*H10*F!$B$43,IF(I10<50%,F10*G10*H10*F!$B$48,IF(I10=50%,F10*G10*H10*F!$B$50,IF(I10=51%,F10*G10*H10*F!$B$51,IF(I10=52%,F10*G10*H10*F!$B$52,IF(I10=53%,F10*G10*H10*F!$B$53,IF(I10=54%,F10*G10*H10*F!$B$54,IF(I10=55%,F10*G10*H10*F!$B$55,IF(I10=56%,F10*G10*H10*F!$B$56,IF(I10=57%,F10*G10*H10*F!$B$57,IF(I10=58%,F10*G10*H10*F!$B$58,IF(I10=59%,F10*G10*H10*F!$B$59,IF(I10=60%,F10*G10*H10*F!$B$60,IF(I10=61%,F10*G10*H10*F!$B$61,IF(I10=62%,F10*G10*H10*F!$B$62,IF(I10=63%,F10*G10*H10*F!$B$63,IF(I10=64%,F10*G10*H10*F!$B$64,IF(I10=65%,F10*G10*H10*F!$B$65,IF(I10=66%,F10*G10*H10*F!$B$66,IF(I10=67%,F10*G10*H10*F!$B$67,IF(I10=68%,F10*G10*H10*F!$B$68,IF(I10=69%,F10*G10*H10*F!$B$69,IF(I10=70%,F10*G10*H10*F!$B$70,IF(I10=71%,F10*G10*H10*F!$B$71,IF(I10=72%,F10*G10*H10*F!$B$72,IF(I10=73%,F10*G10*H10*F!$B$73,IF(I10=74%,F10*G10*H10*F!$B$74,IF(I10=75%,F10*G10*H10*F!$B$75,IF(I10=76%,F10*G10*H10*F!$B$76,IF(I10=77%,F10*G10*H10*F!$B$77,IF(I10=78%,F10*G10*H10*F!$B$78,IF(I10=79%,F10*G10*H10*F!$B$79,IF(I10=80%,F10*G10*H10*F!$B$80,IF(I10=81%,F10*G10*H10*F!$B$81,IF(I10=82%,F10*G10*H10*F!$B$82,IF(I10=83%,F10*G10*H10*F!$B$83,IF(I10=84%,F10*G10*H10*F!$B$84,IF(I10=85%,F10*G10*H10*F!$B$85,IF(I10=86%,F10*G10*H10*F!$B$86,IF(I10=87%,F10*G10*H10*F!$B$87,IF(I10=88%,F10*G10*H10*F!$B$88,IF(I10=89%,F10*G10*H10*F!$B$89,IF(I10=90%,F10*G10*H10*F!$B$90,IF(I10=91%,F10*G10*H10*F!$B$91,IF(I10=92%,F10*G10*H10*F!$B$92,IF(I10=93%,F10*G10*H10*F!$B$93,IF(I10=94%,F10*G10*H10*F!$B$94,IF(I10=95%,F10*G10*H10*F!$B$95,IF(I10=96%,F10*G10*H10*F!$B$96,IF(I10=97%,F10*G10*H10*F!$B$97,IF(I10=98%,F10*G10*H10*F!$B$98,IF(I10=99%,F10*G10*H10*F!$B$99,IF(I10>99%,F10*G10*H10*F!$B$100,))))))))))))))))))))))))))))))))))))))))))))))))))))))))+IF(M10<30%,0,IF(M10<35%,J10*K10*L10*F!$B$33,IF(M10<40%,J10*K10*L10*F!$B$38,IF(M10<45%,J10*K10*L10*F!$B$43,IF(M10<50%,J10*K10*L10*F!$B$48,IF(M10=50%,J10*K10*L10*F!$B$50,IF(M10=51%,J10*K10*L10*F!$B$51,IF(M10=52%,J10*K10*L10*F!$B$52,IF(M10=53%,J10*K10*L10*F!$B$53,IF(M10=54%,J10*K10*L10*F!$B$54,IF(M10=55%,J10*K10*L10*F!$B$55,IF(M10=56%,J10*K10*L10*F!$B$56,IF(M10=57%,J10*K10*L10*F!$B$57,IF(M10=58%,J10*K10*L10*F!$B$58,IF(M10=59%,J10*K10*L10*F!$B$59,IF(M10=60%,J10*K10*L10*F!$B$60,IF(M10=61%,J10*K10*L10*F!$B$61,IF(M10=62%,J10*K10*L10*F!$B$62,IF(M10=63%,J10*K10*L10*F!$B$63,IF(M10=64%,J10*K10*L10*F!$B$64,IF(M10=65%,J10*K10*L10*F!$B$65,IF(M10=66%,J10*K10*L10*F!$B$66,IF(M10=67%,J10*K10*L10*F!$B$67,IF(M10=68%,J10*K10*L10*F!$B$68,IF(M10=69%,J10*K10*L10*F!$B$69,IF(M10=70%,J10*K10*L10*F!$B$70,IF(M10=71%,J10*K10*L10*F!$B$71,IF(M10=72%,J10*K10*L10*F!$B$72,IF(M10=73%,J10*K10*L10*F!$B$73,IF(M10=74%,J10*K10*L10*F!$B$74,IF(M10=75%,J10*K10*L10*F!$B$75,IF(M10=76%,J10*K10*L10*F!$B$76,IF(M10=77%,J10*K10*L10*F!$B$77,IF(M10=78%,J10*K10*L10*F!$B$78,IF(M10=79%,J10*K10*L10*F!$B$79,IF(M10=80%,J10*K10*L10*F!$B$80,IF(M10=81%,J10*K10*L10*F!$B$81,IF(M10=82%,J10*K10*L10*F!$B$82,IF(M10=83%,J10*K10*L10*F!$B$83,IF(M10=84%,J10*K10*L10*F!$B$84,IF(M10=85%,J10*K10*L10*F!$B$85,IF(M10=86%,J10*K10*L10*F!$B$86,IF(M10=87%,J10*K10*L10*F!$B$87,IF(M10=88%,J10*K10*L10*F!$B$88,IF(M10=89%,J10*K10*L10*F!$B$89,IF(M10=90%,J10*K10*L10*F!$B$90,IF(M10=91%,J10*K10*L10*F!$B$91,IF(M10=92%,J10*K10*L10*F!$B$92,IF(M10=93%,J10*K10*L10*F!$B$93,IF(M10=94%,J10*K10*L10*F!$B$94,IF(M10=95%,J10*K10*L10*F!$B$95,IF(M10=96%,J10*K10*L10*F!$B$96,IF(M10=97%,J10*K10*L10*F!$B$97,IF(M10=98%,J10*K10*L10*F!$B$98,IF(M10=99%,J10*K10*L10*F!$B$99,IF(M10>99%,J10*K10*L10*F!$B$100,))))))))))))))))))))))))))))))))))))))))))))))))))))))))+IF(Q10<30%,0,IF(Q10<35%,N10*O10*P10*F!$B$33,IF(Q10<40%,N10*O10*P10*F!$B$38,IF(Q10<45%,N10*O10*P10*F!$B$43,IF(Q10<50%,N10*O10*P10*F!$B$48,IF(Q10=50%,N10*O10*P10*F!$B$50,IF(Q10=51%,N10*O10*P10*F!$B$51,IF(Q10=52%,N10*O10*P10*F!$B$52,IF(Q10=53%,N10*O10*P10*F!$B$53,IF(Q10=54%,N10*O10*P10*F!$B$54,IF(Q10=55%,N10*O10*P10*F!$B$55,IF(Q10=56%,N10*O10*P10*F!$B$56,IF(Q10=57%,N10*O10*P10*F!$B$57,IF(Q10=58%,N10*O10*P10*F!$B$58,IF(Q10=59%,N10*O10*P10*F!$B$59,IF(Q10=60%,N10*O10*P10*F!$B$60,IF(Q10=61%,N10*O10*P10*F!$B$61,IF(Q10=62%,N10*O10*P10*F!$B$62,IF(Q10=63%,N10*O10*P10*F!$B$63,IF(Q10=64%,N10*O10*P10*F!$B$64,IF(Q10=65%,N10*O10*P10*F!$B$65,IF(Q10=66%,N10*O10*P10*F!$B$66,IF(Q10=67%,N10*O10*P10*F!$B$67,IF(Q10=68%,N10*O10*P10*F!$B$68,IF(Q10=69%,N10*O10*P10*F!$B$69,IF(Q10=70%,N10*O10*P10*F!$B$70,IF(Q10=71%,N10*O10*P10*F!$B$71,IF(Q10=72%,N10*O10*P10*F!$B$72,IF(Q10=73%,N10*O10*P10*F!$B$73,IF(Q10=74%,N10*O10*P10*F!$B$74,IF(Q10=75%,N10*O10*P10*F!$B$75,IF(Q10=76%,N10*O10*P10*F!$B$76,IF(Q10=77%,N10*O10*P10*F!$B$77,IF(Q10=78%,N10*O10*P10*F!$B$78,IF(Q10=79%,N10*O10*P10*F!$B$79,IF(Q10=80%,N10*O10*P10*F!$B$80,IF(Q10=81%,N10*O10*P10*F!$B$81,IF(Q10=82%,N10*O10*P10*F!$B$82,IF(Q10=83%,N10*O10*P10*F!$B$83,IF(Q10=84%,N10*O10*P10*F!$B$84,IF(Q10=85%,N10*O10*P10*F!$B$85,IF(Q10=86%,N10*O10*P10*F!$B$86,IF(Q10=87%,N10*O10*P10*F!$B$87,IF(Q10=88%,N10*O10*P10*F!$B$88,IF(Q10=89%,N10*O10*P10*F!$B$89,IF(Q10=90%,N10*O10*P10*F!$B$90,IF(Q10=91%,N10*O10*P10*F!$B$91,IF(Q10=92%,N10*O10*P10*F!$B$92,IF(Q10=93%,N10*O10*P10*F!$B$93,IF(Q10=94%,N10*O10*P10*F!$B$94,IF(Q10=95%,N10*O10*P10*F!$B$95,IF(Q10=96%,N10*O10*P10*F!$B$96,IF(Q10=97%,N10*O10*P10*F!$B$97,IF(Q10=98%,N10*O10*P10*F!$B$98,IF(Q10=99%,N10*O10*P10*F!$B$99,IF(Q10>99%,N10*O10*P10*F!$B$100,))))))))))))))))))))))))))))))))))))))))))))))))))))))))+IF(U10<30%,0,IF(U10<35%,R10*S10*T10*F!$B$33,IF(U10<40%,R10*S10*T10*F!$B$38,IF(U10<45%,R10*S10*T10*F!$B$43,IF(U10<50%,R10*S10*T10*F!$B$48,IF(U10=50%,R10*S10*T10*F!$B$50,IF(U10=51%,R10*S10*T10*F!$B$51,IF(U10=52%,R10*S10*T10*F!$B$52,IF(U10=53%,R10*S10*T10*F!$B$53,IF(U10=54%,R10*S10*T10*F!$B$54,IF(U10=55%,R10*S10*T10*F!$B$55,IF(U10=56%,R10*S10*T10*F!$B$56,IF(U10=57%,R10*S10*T10*F!$B$57,IF(U10=58%,R10*S10*T10*F!$B$58,IF(U10=59%,R10*S10*T10*F!$B$59,IF(U10=60%,R10*S10*T10*F!$B$60,IF(U10=61%,R10*S10*T10*F!$B$61,IF(U10=62%,R10*S10*T10*F!$B$62,IF(U10=63%,R10*S10*T10*F!$B$63,IF(U10=64%,R10*S10*T10*F!$B$64,IF(U10=65%,R10*S10*T10*F!$B$65,IF(U10=66%,R10*S10*T10*F!$B$66,IF(U10=67%,R10*S10*T10*F!$B$67,IF(U10=68%,R10*S10*T10*F!$B$68,IF(U10=69%,R10*S10*T10*F!$B$69,IF(U10=70%,R10*S10*T10*F!$B$70,IF(U10=71%,R10*S10*T10*F!$B$71,IF(U10=72%,R10*S10*T10*F!$B$72,IF(U10=73%,R10*S10*T10*F!$B$73,IF(U10=74%,R10*S10*T10*F!$B$74,IF(U10=75%,R10*S10*T10*F!$B$75,IF(U10=76%,R10*S10*T10*F!$B$76,IF(U10=77%,R10*S10*T10*F!$B$77,IF(U10=78%,R10*S10*T10*F!$B$78,IF(U10=79%,R10*S10*T10*F!$B$79,IF(U10=80%,R10*S10*T10*F!$B$80,IF(U10=81%,R10*S10*T10*F!$B$81,IF(U10=82%,R10*S10*T10*F!$B$82,IF(U10=83%,R10*S10*T10*F!$B$83,IF(U10=84%,R10*S10*T10*F!$B$84,IF(U10=85%,R10*S10*T10*F!$B$85,IF(U10=86%,R10*S10*T10*F!$B$86,IF(U10=87%,R10*S10*T10*F!$B$87,IF(U10=88%,R10*S10*T10*F!$B$88,IF(U10=89%,R10*S10*T10*F!$B$89,IF(U10=90%,R10*S10*T10*F!$B$90,IF(U10=91%,R10*S10*T10*F!$B$91,IF(U10=92%,R10*S10*T10*F!$B$92,IF(U10=93%,R10*S10*T10*F!$B$93,IF(U10=94%,R10*S10*T10*F!$B$94,IF(U10=95%,R10*S10*T10*F!$B$95,IF(U10=96%,R10*S10*T10*F!$B$96,IF(U10=97%,R10*S10*T10*F!$B$97,IF(U10=98%,R10*S10*T10*F!$B$98,IF(U10=99%,R10*S10*T10*F!$B$99,IF(U10>99%,R10*S10*T10*F!$B$100)))))))))))))))))))))))))))))))))))))))))))))))))))))))))*IF(ISNUMBER(E10),E10,1)*IF(ISNUMBER(D10),D10,1) -> #REF! | AA10: =G10*H10+K10*L10+O10*P10+S10*T10 -> 52 | AB10: =(H10*(IF(I10<45%,0.5,IF(I10<55%,0.8,IF(I10<65%,0.9,IF(I10<75%,1,IF(I10<85%,1.1,1.2))))))+L10*(IF(M10<45%,0.5,IF(M10<55%,0.8,IF(M10<65%,0.9,IF(M10<75%,1,IF(M10<85%,1.1,1.2))))))+P10*(IF(Q10<45%,0.5,IF(Q10<55%,0.8,IF(Q10<65%,0.9,IF(Q10<75%,1,IF(Q10<85%,1.1,1.2))))))+T10*(IF(U10<45%,0.5,IF(U10<55%,0.8,IF(U10<65%,0.9,IF(U10<75%,1,IF(U10<85%,1.1,1.2)))))))*IF(D10>=0.8,6,IF(D10<=0.4,1.5,3)) -> 24.6
